Workbook

Sheet Instrucciones
A1: NUESTRO ALFAJOR — SISTEMA DE PRODUCCIÓN
A3: 1. Cargar un pedido
A4: Hoja Pedidos (oculta). Fecha de entrega, cliente, cantidades → remito para WhatsApp automático.
A6: 2. Planificar un día
A7: Hoja Panel: elegí la fecha de entrega. Amasijo-Horneado, Relleno-Glase y Armado-Packaging se actualizan solos con los pedidos de ese día — cuánto hay que producir y cuánto falta comprar (según el Stock real).
A9: 3. Marcar pedidos entregados
A10: En Pedidos, columna Estado → 'Entregado'. Esto dispara el consumo de packaging del Stock (bandejas, bolsas, cajas, etiquetas).
A12: 4. Cargar Producción Real (al cierre del día)
A13: Hoja Producción Real: cuántos amasijos se hicieron de verdad, cuántas tapas se asignaron a cada línea, y cuánto salió armado realmente por línea (Maicena, Frutal, Santafesino, cada variedad de Pepas). Con esto el sistema calcula: (a) la MERMA real de cada línea, y (b) descuenta del Stock los insumos de masa y relleno que realmente se consumieron — no lo que se había planeado.
A15: 5. Registrar compras recibidas
A16: Hoja Orden de Compra, tabla 'Registro de Recepciones' (fila 42 en adelante): cada vez que llega un pedido de un proveedor, cargá fecha, insumo y cantidad. Se suma solo al Stock.
A18: 6. Stock (hoja oculta)
... A28: La primera vez: contá el stock físico real de cada insumo y cargalo en Stock, columna 'Stock inicial'. Si no lo hacés, el sistema va a asumir que arrancás de cero y los 'faltantes' van a salir inflados los primeros días.

Sheet Panel
A1: PANEL DE PRODUCCIÓN — NUESTRO ALFAJOR
A2: Elegí la fecha de entrega a planificar. Todas las hojas de producción se actualizan solas.
A4: FECHA DE ENTREGA A PRODUCIR:
A6: RESUMEN DE PEDIDOS PARA ESA FECHA (unidades — sin montos)
A7: Línea | B7: Paquetes/Bandejas pedidos | C7: Alfajores/Pepas equivalentes
A8: Maicena x7 | B8: =SUMIFS(Pedidos!$F$5:$F$204,Pedidos!$C$5:$C$204,$D$4) | C8: =B8*7
A9: Frutal x7 | B9: =SUMIFS(Pedidos!$G$5:$G$204,Pedidos!$C$5:$C$204,$D$4) | C9: =B9*7
A10: Santafesino x7 | B10: =SUMIFS(Pedidos!$H$5:$H$204,Pedidos!$C$5:$C$204,$D$4) | C10: =B10*7
A11: Maicena x14 | B11: =SUMIFS(Pedidos!$I$5:$I$204,Pedidos!$C$5:$C$204,$D$4) | C11: =B11*14
A12: Pepas DDL | B12: =SUMIFS(Pedidos!$J$5:$J$204,Pedidos!$C$5:$C$204,$D$4) | C12: =B12*1
A13: Pepas Membrillo | B13: =SUMIFS(Pedidos!$K$5:$K$204,Pedidos!$C$5:$C$204,$D$4) | C13: =B13*1
A14: Pepas Arándano | B14: =SUMIFS(Pedidos!$L$5:$L$204,Pedidos!$C$5:$C$204,$D$4) | C14: =B14*1
A15: Pepas Batata | B15: =SUMIFS(Pedidos!$M$5:$M$204,Pedidos!$C$5:$C$204,$D$4) | C15: =B15*1
A16: Pepas Frutos Bosque | B16: =SUMIFS(Pedidos!$N$5:$N$204,Pedidos!$C$5:$C$204,$D$4) | C16: =B16*1
A17: TOTAL | B17: =SUM(B8:B16) | C17: =SUM(C8:C16)
A19: Hojas de producción →
A20: · Amasijo-Horneado: cuántos amasijos hacer, insumos de masa, gas.
A21: · Relleno-Glase: DDL, membrillo, glasé y rellenos de pepas necesarios.
A22: · Armado-Packaging: bandejas, bolsas, cajas y etiquetas necesarias.

Sheet Pedidos
A1: NUESTRO ALFAJOR — SISTEMA DE PEDIDOS Y REMITOS
A2: Cargá la venta 3 días antes de la entrega. El remito para WhatsApp se genera solo →
A4: ID | B4: Fecha Pedido | C4: Fecha Entrega | D4: Cliente | E4: Ciudad | F4: Maicena x7 | G4: Frutal x7 | H4: Santafesino x7 | I4: Maicena x14 | J4: Pepas DDL | K4: Pepas Membrillo | L4: Pepas Arándano | M4: Pepas Batata | N4: Pepas Frutos Bosque | O4: Total Paquetes/Band. | P4: Total $ | Q4: Estado | R4: Remito WhatsApp (copiar y pegar) | T4: PrecioX7 | U4: PrecioX14 | V4: PrecioPepas
A5: =IF(D5="","",ROW()-4) | O5: =IF(D5="","",SUM(F5:N5)) | P5: =IF(D5="","",(F5+G5+H5)*T5+I5*U5+(J5+K5+L5+M5+N5)*V5) | R5: =IF(OR(D5="",O5=0),"","🥮 *NUESTRO ALFAJOR*"&CHAR(10)&"Remito N° "&A5&CHAR(10)&"Fecha entrega: "&TEXT(C5,"DD/MM/YYYY")&CHAR(10)&"Cliente: "&D5&IF(E5<>"",", "&E5,"")&CHAR(10)&"................................."&CHAR(10)&IF(F5>0,"Alfajor Maicena x7: "&F5&" pack. x $"&TEXT($T5,"#,##0")&" = $"&TEXT(F5*$T5,"#,##0")&CHAR(10),"")&IF(G5>0,"Alfajor Frutal x7: "&G5&" pack. x $"&TEXT($T5,"#,##0")&" = $"&TEXT(G5*$T5,"#,##0")&CHAR(10),"")&IF(H5>0,"Alfajor Santafesino x7: "&H5&" pack. x $"&TEXT($T5,"#,##0")&" = $"&TEXT(H5*$T5,"#,##0")&CHAR(10),"")&IF(I5>0,"Alfajor Maicena x14: "&I5&" pack. x $"&TEXT($U5,"#,##0")&" = $"&TEXT(I5*$U5,"#,##0")&CHAR(10),"")&IF(J5>0,"Pepas DDL: "&J5&" band. x $"&TEXT($V5,"#,##0")&" = $"&TEXT(J5*$V5,"#,##0")&CHAR(10),"")&IF(K5>0,"Pepas Membrillo: "&K5&" band. x $"&TEXT($V5,"#,##0")&" = $"&TEXT(K5*$V5,"#,##0")&CHAR(10),"")&IF(L5>0,"Pepas Arándano: "&L5&" band. x $"&TEXT($V5,"#,##0")&" = $"&TEXT(L5*$V5,"#,##0")&CHAR(10),"")&IF(M5>0,"Pepas Batata: "&M5&" band. x $"&TEXT($V5,"#,##0")&" = $"&TEXT(M5*$V5,"#,##0")&CHAR(10),"")&IF(N5>0,"Pepas Frutos del Bosque: "&N5&" band. x $"&TEXT($V5,"#,##0")&" = $"&TEXT(N5*$V5,"#,##0")&CHAR(10),"")&"................................."&CHAR(10)&"*TOTAL: $"&TEXT(P5,"#,##0")&"*"&CHAR(10)&CHAR(10)&"¡Gracias por tu pedido! 🙏") | T5: =IF(C5="",Config!$B$5,IF(C5>=Config!$B$2,Config!$C$5,Config!$B$5)) | U5: =IF(C5="",Config!$B$8,IF(C5>=Config!$B$2,Config!$C$8,Config!$B$8)) | V5: =IF(C5="",Config!$B$9,IF(C5>=Config!$B$2,Config!$C$9,Config!$B$9))
A6: =IF(D6="","",ROW()-4) | O6: =IF(D6="","",SUM(F6:N6)) | P6: =IF(D6="","",(F6+G6+H6)*T6+I6*U6+(J6+K6+L6+M6+N6)*V6) | R6: =IF(OR(D6="",O6=0),"","🥮 *NUESTRO ALFAJOR*"&CHAR(10)&"Remito N° "&A6&CHAR(10)&"Fecha entrega: "&TEXT(C6,"DD/MM/YYYY")&CHAR(10)&"Cliente: "&D6&IF(E6<>"",", "&E6,"")&CHAR(10)&"................................."&CHAR(10)&IF(F6>0,"Alfajor Maicena x7: "&F6&" pack. x $"&TEXT($T6,"#,##0")&" = $"&TEXT(F6*$T6,"#,##0")&CHAR(10),"")&IF(G6>0,"Alfajor Frutal x7: "&G6&" pack. x $"&TEXT($T6,"#,##0")&" = $"&TEXT(G6*$T6,"#,##0")&CHAR(10),"")&IF(H6>0,"Alfajor Santafesino x7: "&H6&" pack. x $"&TEXT($T6,"#,##0")&" = $"&TEXT(H6*$T6,"#,##0")&CHAR(10),"")&IF(I6>0,"Alfajor Maicena x14: "&I6&" pack. x $"&TEXT($U6,"#,##0")&" = $"&TEXT(I6*$U6,"#,##0")&CHAR(10),"")&IF(J6>0,"Pepas DDL: "&J6&" band. x $"&TEXT($V6,"#,##0")&" = $"&TEXT(J6*$V6,"#,##0")&CHAR(10),"")&IF(K6>0,"Pepas Membrillo: "&K6&" band. x $"&TEXT($V6,"#,##0")&" = $"&TEXT(K6*$V6,"#,##0")&CHAR(10),"")&IF(L6>0,"Pepas Arándano: "&L6&" band. x $"&TEXT($V6,"#,##0")&" = $"&TEXT(L6*$V6,"#,##0")&CHAR(10),"")&IF(M6>0,"Pepas Batata: "&M6&" band. x $"&TEXT($V6,"#,##0")&" = $"&TEXT(M6*$V6,"#,##0")&CHAR(10),"")&IF(N6>0,"Pepas Frutos del Bosque: "&N6&" band. x $"&TEXT($V6,"#,##0")&" = $"&TEXT(N6*$V6,"#,##0")&CHAR(10),"")&"................................."&CHAR(10)&"*TOTAL: $"&TEXT(P6,"#,##0")&"*"&CHAR(10)&CHAR(10)&"¡Gracias por tu pedido! 🙏") | T6: =IF(C6="",Config!$B$5,IF(C6>=Config!$B$2,Config!$C$5,Config!$B$5)) | U6: =IF(C6="",Config!$B$8,IF(C6>=Config!$B$2,Config!$C$8,Config!$B$8)) | V6: =IF(C6="",Config!$B$9,IF(C6>=Config!$B$2,Config!$C$9,Config!$B$9))
A7: =IF(D7="","",ROW()-4) | O7: =IF(D7="","",SUM(F7:N7)) | P7: =IF(D7="","",(F7+G7+H7)*T7+I7*U7+(J7+K7+L7+M7+N7)*V7) | R7: =IF(OR(D7="",O7=0),"","🥮 *NUESTRO ALFAJOR*"&CHAR(10)&"Remito N° "&A7&CHAR(10)&"Fecha entrega: "&TEXT(C7,"DD/MM/YYYY")&CHAR(10)&"Cliente: "&D7&IF(E7<>"",", "&E7,"")&CHAR(10)&"................................."&CHAR(10)&IF(F7>0,"Alfajor Maicena x7: "&F7&" pack. x $"&TEXT($T7,"#,##0")&" = $"&TEXT(F7*$T7,"#,##0")&CHAR(10),"")&IF(G7>0,"Alfajor Frutal x7: "&G7&" pack. x $"&TEXT($T7,"#,##0")&" = $"&TEXT(G7*$T7,"#,##0")&CHAR(10),"")&IF(H7>0,"Alfajor Santafesino x7: "&H7&" pack. x $"&TEXT($T7,"#,##0")&" = $"&TEXT(H7*$T7,"#,##0")&CHAR(10),"")&IF(I7>0,"Alfajor Maicena x14: "&I7&" pack. x $"&TEXT($U7,"#,##0")&" = $"&TEXT(I7*$U7,"#,##0")&CHAR(10),"")&IF(J7>0,"Pepas DDL: "&J7&" band. x $"&TEXT($V7,"#,##0")&" = $"&TEXT(J7*$V7,"#,##0")&CHAR(10),"")&IF(K7>0,"Pepas Membrillo: "&K7&" band. x $"&TEXT($V7,"#,##0")&" = $"&TEXT(K7*$V7,"#,##0")&CHAR(10),"")&IF(L7>0,"Pepas Arándano: "&L7&" band. x $"&TEXT($V7,"#,##0")&" = $"&TEXT(L7*$V7,"#,##0")&CHAR(10),"")&IF(M7>0,"Pepas Batata: "&M7&" band. x $"&TEXT($V7,"#,##0")&" = $"&TEXT(M7*$V7,"#,##0")&CHAR(10),"")&IF(N7>0,"Pepas Frutos del Bosque: "&N7&" band. x $"&TEXT($V7,"#,##0")&" = $"&TEXT(N7*$V7,"#,##0")&CHAR(10),"")&"................................."&CHAR(10)&"*TOTAL: $"&TEXT(P7,"#,##0")&"*"&CHAR(10)&CHAR(10)&"¡Gracias por tu pedido! 🙏") | T7: =IF(C7="",Config!$B$5,IF(C7>=Config!$B$2,Config!$C$5,Config!$B$5)) | U7: =IF(C7="",Config!$B$8,IF(C7>=Config!$B$2,Config!$C$8,Config!$B$8)) | V7: =IF(C7="",Config!$B$9,IF(C7>=Config!$B$2,Config!$C$9,Config!$B$9))
A8: =IF(D8="","",ROW()-4) | O8: =IF(D8="","",SUM(F8:N8)) | P8: =IF(D8="","",(F8+G8+H8)*T8+I8*U8+(J8+K8+L8+M8+N8)*V8) | R8: =IF(OR(D8="",O8=0),"","🥮 *NUESTRO ALFAJOR*"&CHAR(10)&"Remito N° "&A8&CHAR(10)&"Fecha entrega: "&TEXT(C8,"DD/MM/YYYY")&CHAR(10)&"Cliente: "&D8&IF(E8<>"",", "&E8,"")&CHAR(10)&"................................."&CHAR(10)&IF(F8>0,"Alfajor Maicena x7: "&F8&" pack. x $"&TEXT($T8,"#,##0")&" = $"&TEXT(F8*$T8,"#,##0")&CHAR(10),"")&IF(G8>0,"Alfajor Frutal x7: "&G8&" pack. x $"&TEXT($T8,"#,##0")&" = $"&TEXT(G8*$T8,"#,##0")&CHAR(10),"")&IF(H8>0,"Alfajor Santafesino x7: "&H8&" pack. x $"&TEXT($T8,"#,##0")&" = $"&TEXT(H8*$T8,"#,##0")&CHAR(10),"")&IF(I8>0,"Alfajor Maicena x14: "&I8&" pack. x $"&TEXT($U8,"#,##0")&" = $"&TEXT(I8*$U8,"#,##0")&CHAR(10),"")&IF(J8>0,"Pepas DDL: "&J8&" band. x $"&TEXT($V8,"#,##0")&" = $"&TEXT(J8*$V8,"#,##0")&CHAR(10),"")&IF(K8>0,"Pepas Membrillo: "&K8&" band. x $"&TEXT($V8,"#,##0")&" = $"&TEXT(K8*$V8,"#,##0")&CHAR(10),"")&IF(L8>0,"Pepas Arándano: "&L8&" band. x $"&TEXT($V8,"#,##0")&" = $"&TEXT(L8*$V8,"#,##0")&CHAR(10),"")&IF(M8>0,"Pepas Batata: "&M8&" band. x $"&TEXT($V8,"#,##0")&" = $"&TEXT(M8*$V8,"#,##0")&CHAR(10),"")&IF(N8>0,"Pepas Frutos del Bosque: "&N8&" band. x $"&TEXT($V8,"#,##0")&" = $"&TEXT(N8*$V8,"#,##0")&CHAR(10),"")&"................................."&CHAR(10)&"*TOTAL: $"&TEXT(P8,"#,##0")&"*"&CHAR(10)&CHAR(10)&"¡Gracias por tu pedido! 🙏") | T8: =IF(C8="",Config!$B$5,IF(C8>=Config!$B$2,Config!$C$5,Config!$B$5)) | U8: =IF(C8="",Config!$B$8,IF(C8>=Config!$B$2,Config!$C$8,Config!$B$8)) | V8: =IF(C8="",Config!$B$9,IF(C8>=Config!$B$2,Config!$C$9,Config!$B$9))
A9: =IF(D9="","",ROW()-4) | O9: =IF(D9="","",SUM(F9:N9)) | P9: =IF(D9="","",(F9+G9+H9)*T9+I9*U9+(J9+K9+L9+M9+N9)*V9) | R9: =IF(OR(D9="",O9=0),"","🥮 *NUESTRO ALFAJOR*"&CHAR(10)&"Remito N° "&A9&CHAR(10)&"Fecha entrega: "&TEXT(C9,"DD/MM/YYYY")&CHAR(10)&"Cliente: "&D9&IF(E9<>"",", "&E9,"")&CHAR(10)&"................................."&CHAR(10)&IF(F9>0,"Alfajor Maicena x7: "&F9&" pack. x $"&TEXT($T9,"#,##0")&" = $"&TEXT(F9*$T9,"#,##0")&CHAR(10),"")&IF(G9>0,"Alfajor Frutal x7: "&G9&" pack. x $"&TEXT($T9,"#,##0")&" = $"&TEXT(G9*$T9,"#,##0")&CHAR(10),"")&IF(H9>0,"Alfajor Santafesino x7: "&H9&" pack. x $"&TEXT($T9,"#,##0")&" = $"&TEXT(H9*$T9,"#,##0")&CHAR(10),"")&IF(I9>0,"Alfajor Maicena x14: "&I9&" pack. x $"&TEXT($U9,"#,##0")&" = $"&TEXT(I9*$U9,"#,##0")&CHAR(10),"")&IF(J9>0,"Pepas DDL: "&J9&" band. x $"&TEXT($V9,"#,##0")&" = $"&TEXT(J9*$V9,"#,##0")&CHAR(10),"")&IF(K9>0,"Pepas Membrillo: "&K9&" band. x $"&TEXT($V9,"#,##0")&" = $"&TEXT(K9*$V9,"#,##0")&CHAR(10),"")&IF(L9>0,"Pepas Arándano: "&L9&" band. x $"&TEXT($V9,"#,##0")&" = $"&TEXT(L9*$V9,"#,##0")&CHAR(10),"")&IF(M9>0,"Pepas Batata: "&M9&" band. x $"&TEXT($V9,"#,##0")&" = $"&TEXT(M9*$V9,"#,##0")&CHAR(10),"")&IF(N9>0,"Pepas Frutos del Bosque: "&N9&" band. x $"&TEXT($V9,"#,##0")&" = $"&TEXT(N9*$V9,"#,##0")&CHAR(10),"")&"................................."&CHAR(10)&"*TOTAL: $"&TEXT(P9,"#,##0")&"*"&CHAR(10)&CHAR(10)&"¡Gracias por tu pedido! 🙏") | T9: =IF(C9="",Config!$B$5,IF(C9>=Config!$B$2,Config!$C$5,Config!$B$5)) | U9: =IF(C9="",Config!$B$8,IF(C9>=Config!$B$2,Config!$C$8,Config!$B$8)) | V9: =IF(C9="",Config!$B$9,IF(C9>=Config!$B$2,Config!$C$9,Config!$B$9))
A10: =IF(D10="","",ROW()-4) | O10: =IF(D10="","",SUM(F10:N10)) | P10: =IF(D10="","",(F10+G10+H10)*T10+I10*U10+(J10+K10+L10+M10+N10)*V10) | R10: =IF(OR(D10="",O10=0),"","🥮 *NUESTRO ALFAJOR*"&CHAR(10)&"Remito N° "&A10&CHAR(10)&"Fecha entrega: "&TEXT(C10,"DD/MM/YYYY")&CHAR(10)&"Cliente: "&D10&IF(E10<>"",", "&E10,"")&CHAR(10)&"................................."&CHAR(10)&IF(F10>0,"Alfajor Maicena x7: "&F10&" pack. x $"&TEXT($T10,"#,##0")&" = $"&TEXT(F10*$T10,"#,##0")&CHAR(10),"")&IF(G10>0,"Alfajor Frutal x7: "&G10&" pack. x $"&TEXT($T10,"#,##0")&" = $"&TEXT(G10*$T10,"#,##0")&CHAR(10),"")&IF(H10>0,"Alfajor Santafesino x7: "&H10&" pack. x $"&TEXT($T10,"#,##0")&" = $"&TEXT(H10*$T10,"#,##0")&CHAR(10),"")&IF(I10>0,"Alfajor Maicena x14: "&I10&" pack. x $"&TEXT($U10,"#,##0")&" = $"&TEXT(I10*$U10,"#,##0")&CHAR(10),"")&IF(J10>0,"Pepas DDL: "&J10&" band. x $"&TEXT($V10,"#,##0")&" = $"&TEXT(J10*$V10,"#,##0")&CHAR(10),"")&IF(K10>0,"Pepas Membrillo: "&K10&" band. x $"&TEXT($V10,"#,##0")&" = $"&TEXT(K10*$V10,"#,##0")&CHAR(10),"")&IF(L10>0,"Pepas Arándano: "&L10&" band. x $"&TEXT($V10,"#,##0")&" = $"&TEXT(L10*$V10,"#,##0")&CHAR(10),"")&IF(M10>0,"Pepas Batata: "&M10&" band. x $"&TEXT($V10,"#,##0")&" = $"&TEXT(M10*$V10,"#,##0")&CHAR(10),"")&IF(N10>0,"Pepas Frutos del Bosque: "&N10&" band. x $"&TEXT($V10,"#,##0")&" = $"&TEXT(N10*$V10,"#,##0")&CHAR(10),"")&"................................."&CHAR(10)&"*TOTAL: $"&TEXT(P10,"#,##0")&"*"&CHAR(10)&CHAR(10)&"¡Gracias por tu pedido! 🙏") | T10: =IF(C10="",Config!$B$5,IF(C10>=Config!$B$2,Config!$C$5,Config!$B$5)) | U10: =IF(C10="",Config!$B$8,IF(C10>=Config!$B$2,Config!$C$8,Config!$B$8)) | V10: =IF(C10="",Config!$B$9,IF(C10>=Config!$B$2,Config!$C$9,Config!$B$9))
A11: =IF(D11="","",ROW()-4) | O11: =IF(D11="","",SUM(F11:N11)) | P11: =IF(D11="","",(F11+G11+H11)*T11+I11*U11+(J11+K11+L11+M11+N11)*V11) | R11: =IF(OR(D11="",O11=0),"","🥮 *NUESTRO ALFAJOR*"&CHAR(10)&"Remito N° "&A11&CHAR(10)&"Fecha entrega: "&TEXT(C11,"DD/MM/YYYY")&CHAR(10)&"Cliente: "&D11&IF(E11<>"",", "&E11,"")&CHAR(10)&"................................."&CHAR(10)&IF(F11>0,"Alfajor Maicena x7: "&F11&" pack. x $"&TEXT($T11,"#,##0")&" = $"&TEXT(F11*$T11,"#,##0")&CHAR(10),"")&IF(G11>0,"Alfajor Frutal x7: "&G11&" pack. x $"&TEXT($T11,"#,##0")&" = $"&TEXT(G11*$T11,"#,##0")&CHAR(10),"")&IF(H11>0,"Alfajor Santafesino x7: "&H11&" pack. x $"&TEXT($T11,"#,##0")&" = $"&TEXT(H11*$T11,"#,##0")&CHAR(10),"")&IF(I11>0,"Alfajor Maicena x14: "&I11&" pack. x $"&TEXT($U11,"#,##0")&" = $"&TEXT(I11*$U11,"#,##0")&CHAR(10),"")&IF(J11>0,"Pepas DDL: "&J11&" band. x $"&TEXT($V11,"#,##0")&" = $"&TEXT(J11*$V11,"#,##0")&CHAR(10),"")&IF(K11>0,"Pepas Membrillo: "&K11&" band. x $"&TEXT($V11,"#,##0")&" = $"&TEXT(K11*$V11,"#,##0")&CHAR(10),"")&IF(L11>0,"Pepas Arándano: "&L11&" band. x $"&TEXT($V11,"#,##0")&" = $"&TEXT(L11*$V11,"#,##0")&CHAR(10),"")&IF(M11>0,"Pepas Batata: "&M11&" band. x $"&TEXT($V11,"#,##0")&" = $"&TEXT(M11*$V11,"#,##0")&CHAR(10),"")&IF(N11>0,"Pepas Frutos del Bosque: "&N11&" band. x $"&TEXT($V11,"#,##0")&" = $"&TEXT(N11*$V11,"#,##0")&CHAR(10),"")&"................................."&CHAR(10)&"*TOTAL: $"&TEXT(P11,"#,##0")&"*"&CHAR(10)&CHAR(10)&"¡Gracias por tu pedido! 🙏") | T11: =IF(C11="",Config!$B$5,IF(C11>=Config!$B$2,Config!$C$5,Config!$B$5)) | U11: =IF(C11="",Config!$B$8,IF(C11>=Config!$B$2,Config!$C$8,Config!$B$8)) | V11: =IF(C11="",Config!$B$9,IF(C11>=Config!$B$2,Config!$C$9,Config!$B$9))
A12: =IF(D12="","",ROW()-4) | O12: =IF(D12="","",SUM(F12:N12)) | P12: =IF(D12="","",(F12+G12+H12)*T12+I12*U12+(J12+K12+L12+M12+N12)*V12) | R12: =IF(OR(D12="",O12=0),"","🥮 *NUESTRO ALFAJOR*"&CHAR(10)&"Remito N° "&A12&CHAR(10)&"Fecha entrega: "&TEXT(C12,"DD/MM/YYYY")&CHAR(10)&"Cliente: "&D12&IF(E12<>"",", "&E12,"")&CHAR(10)&"................................."&CHAR(10)&IF(F12>0,"Alfajor Maicena x7: "&F12&" pack. x $"&TEXT($T12,"#,##0")&" = $"&TEXT(F12*$T12,"#,##0")&CHAR(10),"")&IF(G12>0,"Alfajor Frutal x7: "&G12&" pack. x $"&TEXT($T12,"#,##0")&" = $"&TEXT(G12*$T12,"#,##0")&CHAR(10),"")&IF(H12>0,"Alfajor Santafesino x7: "&H12&" pack. x $"&TEXT($T12,"#,##0")&" = $"&TEXT(H12*$T12,"#,##0")&CHAR(10),"")&IF(I12>0,"Alfajor Maicena x14: "&I12&" pack. x $"&TEXT($U12,"#,##0")&" = $"&TEXT(I12*$U12,"#,##0")&CHAR(10),"")&IF(J12>0,"Pepas DDL: "&J12&" band. x $"&TEXT($V12,"#,##0")&" = $"&TEXT(J12*$V12,"#,##0")&CHAR(10),"")&IF(K12>0,"Pepas Membrillo: "&K12&" band. x $"&TEXT($V12,"#,##0")&" = $"&TEXT(K12*$V12,"#,##0")&CHAR(10),"")&IF(L12>0,"Pepas Arándano: "&L12&" band. x $"&TEXT($V12,"#,##0")&" = $"&TEXT(L12*$V12,"#,##0")&CHAR(10),"")&IF(M12>0,"Pepas Batata: "&M12&" band. x $"&TEXT($V12,"#,##0")&" = $"&TEXT(M12*$V12,"#,##0")&CHAR(10),"")&IF(N12>0,"Pepas Frutos del Bosque: "&N12&" band. x $"&TEXT($V12,"#,##0")&" = $"&TEXT(N12*$V12,"#,##0")&CHAR(10),"")&"................................."&CHAR(10)&"*TOTAL: $"&TEXT(P12,"#,##0")&"*"&CHAR(10)&CHAR(10)&"¡Gracias por tu pedido! 🙏") | T12: =IF(C12="",Config!$B$5,IF(C12>=Config!$B$2,Config!$C$5,Config!$B$5)) | U12: =IF(C12="",Config!$B$8,IF(C12>=Config!$B$2,Config!$C$8,Config!$B$8)) | V12: =IF(C12="",Config!$B$9,IF(C12>=Config!$B$2,Config!$C$9,Config!$B$9))
A13: =IF(D13="","",ROW()-4) | O13: =IF(D13="","",SUM(F13:N13)) | P13: =IF(D13="","",(F13+G13+H13)*T13+I13*U13+(J13+K13+L13+M13+N13)*V13) | R13: =IF(OR(D13="",O13=0),"","🥮 *NUESTRO ALFAJOR*"&CHAR(10)&"Remito N° "&A13&CHAR(10)&"Fecha entrega: "&TEXT(C13,"DD/MM/YYYY")&CHAR(10)&"Cliente: "&D13&IF(E13<>"",", "&E13,"")&CHAR(10)&"................................."&CHAR(10)&IF(F13>0,"Alfajor Maicena x7: "&F13&" pack. x $"&TEXT($T13,"#,##0")&" = $"&TEXT(F13*$T13,"#,##0")&CHAR(10),"")&IF(G13>0,"Alfajor Frutal x7: "&G13&" pack. x $"&TEXT($T13,"#,##0")&" = $"&TEXT(G13*$T13,"#,##0")&CHAR(10),"")&IF(H13>0,"Alfajor Santafesino x7: "&H13&" pack. x $"&TEXT($T13,"#,##0")&" = $"&TEXT(H13*$T13,"#,##0")&CHAR(10),"")&IF(I13>0,"Alfajor Maicena x14: "&I13&" pack. x $"&TEXT($U13,"#,##0")&" = $"&TEXT(I13*$U13,"#,##0")&CHAR(10),"")&IF(J13>0,"Pepas DDL: "&J13&" band. x $"&TEXT($V13,"#,##0")&" = $"&TEXT(J13*$V13,"#,##0")&CHAR(10),"")&IF(K13>0,"Pepas Membrillo: "&K13&" band. x $"&TEXT($V13,"#,##0")&" = $"&TEXT(K13*$V13,"#,##0")&CHAR(10),"")&IF(L13>0,"Pepas Arándano: "&L13&" band. x $"&TEXT($V13,"#,##0")&" = $"&TEXT(L13*$V13,"#,##0")&CHAR(10),"")&IF(M13>0,"Pepas Batata: "&M13&" band. x $"&TEXT($V13,"#,##0")&" = $"&TEXT(M13*$V13,"#,##0")&CHAR(10),"")&IF(N13>0,"Pepas Frutos del Bosque: "&N13&" band. x $"&TEXT($V13,"#,##0")&" = $"&TEXT(N13*$V13,"#,##0")&CHAR(10),"")&"................................."&CHAR(10)&"*TOTAL: $"&TEXT(P13,"#,##0")&"*"&CHAR(10)&CHAR(10)&"¡Gracias por tu pedido! 🙏") | T13: =IF(C13="",Config!$B$5,IF(C13>=Config!$B$2,Config!$C$5,Config!$B$5)) | U13: =IF(C13="",Config!$B$8,IF(C13>=Config!$B$2,Config!$C$8,Config!$B$8)) | V13: =IF(C13="",Config!$B$9,IF(C13>=Config!$B$2,Config!$C$9,Config!$B$9))
A14: =IF(D14="","",ROW()-4) | O14: =IF(D14="","",SUM(F14:N14)) | P14: =IF(D14="","",(F14+G14+H14)*T14+I14*U14+(J14+K14+L14+M14+N14)*V14) | R14: =IF(OR(D14="",O14=0),"","🥮 *NUESTRO ALFAJOR*"&CHAR(10)&"Remito N° "&A14&CHAR(10)&"Fecha entrega: "&TEXT(C14,"DD/MM/YYYY")&CHAR(10)&"Cliente: "&D14&IF(E14<>"",", "&E14,"")&CHAR(10)&"................................."&CHAR(10)&IF(F14>0,"Alfajor Maicena x7: "&F14&" pack. x $"&TEXT($T14,"#,##0")&" = $"&TEXT(F14*$T14,"#,##0")&CHAR(10),"")&IF(G14>0,"Alfajor Frutal x7: "&G14&" pack. x $"&TEXT($T14,"#,##0")&" = $"&TEXT(G14*$T14,"#,##0")&CHAR(10),"")&IF(H14>0,"Alfajor Santafesino x7: "&H14&" pack. x $"&TEXT($T14,"#,##0")&" = $"&TEXT(H14*$T14,"#,##0")&CHAR(10),"")&IF(I14>0,"Alfajor Maicena x14: "&I14&" pack. x $"&TEXT($U14,"#,##0")&" = $"&TEXT(I14*$U14,"#,##0")&CHAR(10),"")&IF(J14>0,"Pepas DDL: "&J14&" band. x $"&TEXT($V14,"#,##0")&" = $"&TEXT(J14*$V14,"#,##0")&CHAR(10),"")&IF(K14>0,"Pepas Membrillo: "&K14&" band. x $"&TEXT($V14,"#,##0")&" = $"&TEXT(K14*$V14,"#,##0")&CHAR(10),"")&IF(L14>0,"Pepas Arándano: "&L14&" band. x $"&TEXT($V14,"#,##0")&" = $"&TEXT(L14*$V14,"#,##0")&CHAR(10),"")&IF(M14>0,"Pepas Batata: "&M14&" band. x $"&TEXT($V14,"#,##0")&" = $"&TEXT(M14*$V14,"#,##0")&CHAR(10),"")&IF(N14>0,"Pepas Frutos del Bosque: "&N14&" band. x $"&TEXT($V14,"#,##0")&" = $"&TEXT(N14*$V14,"#,##0")&CHAR(10),"")&"................................."&CHAR(10)&"*TOTAL: $"&TEXT(P14,"#,##0")&"*"&CHAR(10)&CHAR(10)&"¡Gracias por tu pedido! 🙏") | T14: =IF(C14="",Config!$B$5,IF(C14>=Config!$B$2,Config!$C$5,Config!$B$5)) | U14: =IF(C14="",Config!$B$8,IF(C14>=Config!$B$2,Config!$C$8,Config!$B$8)) | V14: =IF(C14="",Config!$B$9,IF(C14>=Config!$B$2,Config!$C$9,Config!$B$9))
A15: =IF(D15="","",ROW()-4) | O15: =IF(D15="","",SUM(F15:N15)) | P15: =IF(D15="","",(F15+G15+H15)*T15+I15*U15+(J15+K15+L15+M15+N15)*V15) | R15: =IF(OR(D15="",O15=0),"","🥮 *NUESTRO ALFAJOR*"&CHAR(10)&"Remito N° "&A15&CHAR(10)&"Fecha entrega: "&TEXT(C15,"DD/MM/YYYY")&CHAR(10)&"Cliente: "&D15&IF(E15<>"",", "&E15,"")&CHAR(10)&"................................."&CHAR(10)&IF(F15>0,"Alfajor Maicena x7: "&F15&" pack. x $"&TEXT($T15,"#,##0")&" = $"&TEXT(F15*$T15,"#,##0")&CHAR(10),"")&IF(G15>0,"Alfajor Frutal x7: "&G15&" pack. x $"&TEXT($T15,"#,##0")&" = $"&TEXT(G15*$T15,"#,##0")&CHAR(10),"")&IF(H15>0,"Alfajor Santafesino x7: "&H15&" pack. x $"&TEXT($T15,"#,##0")&" = $"&TEXT(H15*$T15,"#,##0")&CHAR(10),"")&IF(I15>0,"Alfajor Maicena x14: "&I15&" pack. x $"&TEXT($U15,"#,##0")&" = $"&TEXT(I15*$U15,"#,##0")&CHAR(10),"")&IF(J15>0,"Pepas DDL: "&J15&" band. x $"&TEXT($V15,"#,##0")&" = $"&TEXT(J15*$V15,"#,##0")&CHAR(10),"")&IF(K15>0,"Pepas Membrillo: "&K15&" band. x $"&TEXT($V15,"#,##0")&" = $"&TEXT(K15*$V15,"#,##0")&CHAR(10),"")&IF(L15>0,"Pepas Arándano: "&L15&" band. x $"&TEXT($V15,"#,##0")&" = $"&TEXT(L15*$V15,"#,##0")&CHAR(10),"")&IF(M15>0,"Pepas Batata: "&M15&" band. x $"&TEXT($V15,"#,##0")&" = $"&TEXT(M15*$V15,"#,##0")&CHAR(10),"")&IF(N15>0,"Pepas Frutos del Bosque: "&N15&" band. x $"&TEXT($V15,"#,##0")&" = $"&TEXT(N15*$V15,"#,##0")&CHAR(10),"")&"................................."&CHAR(10)&"*TOTAL: $"&TEXT(P15,"#,##0")&"*"&CHAR(10)&CHAR(10)&"¡Gracias por tu pedido! 🙏") | T15: =IF(C15="",Config!$B$5,IF(C15>=Config!$B$2,Config!$C$5,Config!$B$5)) | U15: =IF(C15="",Config!$B$8,IF(C15>=Config!$B$2,Config!$C$8,Config!$B$8)) | V15: =IF(C15="",Config!$B$9,IF(C15>=Config!$B$2,Config!$C$9,Config!$B$9))
A16: =IF(D16="","",ROW()-4) | O16: =IF(D16="","",SUM(F16:N16)) | P16: =IF(D16="","",(F16+G16+H16)*T16+I16*U16+(J16+K16+L16+M16+N16)*V16) | R16: =IF(OR(D16="",O16=0),"","🥮 *NUESTRO ALFAJOR*"&CHAR(10)&"Remito N° "&A16&CHAR(10)&"Fecha entrega: "&TEXT(C16,"DD/MM/YYYY")&CHAR(10)&"Cliente: "&D16&IF(E16<>"",", "&E16,"")&CHAR(10)&"................................."&CHAR(10)&IF(F16>0,"Alfajor Maicena x7: "&F16&" pack. x $"&TEXT($T16,"#,##0")&" = $"&TEXT(F16*$T16,"#,##0")&CHAR(10),"")&IF(G16>0,"Alfajor Frutal x7: "&G16&" pack. x $"&TEXT($T16,"#,##0")&" = $"&TEXT(G16*$T16,"#,##0")&CHAR(10),"")&IF(H16>0,"Alfajor Santafesino x7: "&H16&" pack. x $"&TEXT($T16,"#,##0")&" = $"&TEXT(H16*$T16,"#,##0")&CHAR(10),"")&IF(I16>0,"Alfajor Maicena x14: "&I16&" pack. x $"&TEXT($U16,"#,##0")&" = $"&TEXT(I16*$U16,"#,##0")&CHAR(10),"")&IF(J16>0,"Pepas DDL: "&J16&" band. x $"&TEXT($V16,"#,##0")&" = $"&TEXT(J16*$V16,"#,##0")&CHAR(10),"")&IF(K16>0,"Pepas Membrillo: "&K16&" band. x $"&TEXT($V16,"#,##0")&" = $"&TEXT(K16*$V16,"#,##0")&CHAR(10),"")&IF(L16>0,"Pepas Arándano: "&L16&" band. x $"&TEXT($V16,"#,##0")&" = $"&TEXT(L16*$V16,"#,##0")&CHAR(10),"")&IF(M16>0,"Pepas Batata: "&M16&" band. x $"&TEXT($V16,"#,##0")&" = $"&TEXT(M16*$V16,"#,##0")&CHAR(10),"")&IF(N16>0,"Pepas Frutos del Bosque: "&N16&" band. x $"&TEXT($V16,"#,##0")&" = $"&TEXT(N16*$V16,"#,##0")&CHAR(10),"")&"................................."&CHAR(10)&"*TOTAL: $"&TEXT(P16,"#,##0")&"*"&CHAR(10)&CHAR(10)&"¡Gracias por tu pedido! 🙏") | T16: =IF(C16="",Config!$B$5,IF(C16>=Config!$B$2,Config!$C$5,Config!$B$5)) | U16: =IF(C16="",Config!$B$8,IF(C16>=Config!$B$2,Config!$C$8,Config!$B$8)) | V16: =IF(C16="",Config!$B$9,IF(C16>=Config!$B$2,Config!$C$9,Config!$B$9))
... A204: =IF(D204="","",ROW()-4) | O204: =IF(D204="","",SUM(F204:N204)) | P204: =IF(D204="","",(F204+G204+H204)*T204+I204*U204+(J204+K204+L204+M204+N204)*V204) | R204: =IF(OR(D204="",O204=0),"","🥮 *NUESTRO ALFAJOR*"&CHAR(10)&"Remito N° "&A204&CHAR(10)&"Fecha entrega: "&TEXT(C204,"DD/MM/YYYY")&CHAR(10)&"Cliente: "&D204&IF(E204<>"",", "&E204,"")&CHAR(10)&"................................."&CHAR(10)&IF(F204>0,"Alfajor Maicena x7: "&F204&" pack. x $"&TEXT($T204,"#,##0")&" = $"&TEXT(F204*$T204,"#,##0")&CHAR(10),"")&IF(G204>0,"Alfajor Frutal x7: "&G204&" pack. x $"&TEXT($T204,"#,##0")&" = $"&TEXT(G204*$T204,"#,##0")&CHAR(10),"")&IF(H204>0,"Alfajor Santafesino x7: "&H204&" pack. x $"&TEXT($T204,"#,##0")&" = $"&TEXT(H204*$T204,"#,##0")&CHAR(10),"")&IF(I204>0,"Alfajor Maicena x14: "&I204&" pack. x $"&TEXT($U204,"#,##0")&" = $"&TEXT(I204*$U204,"#,##0")&CHAR(10),"")&IF(J204>0,"Pepas DDL: "&J204&" band. x $"&TEXT($V204,"#,##0")&" = $"&TEXT(J204*$V204,"#,##0")&CHAR(10),"")&IF(K204>0,"Pepas Membrillo: "&K204&" band. x $"&TEXT($V204,"#,##0")&" = $"&TEXT(K204*$V204,"#,##0")&CHAR(10),"")&IF(L204>0,"Pepas Arándano: "&L204&" band. x $"&TEXT($V204,"#,##0")&" = $"&TEXT(L204*$V204,"#,##0")&CHAR(10),"")&IF(M204>0,"Pepas Batata: "&M204&" band. x $"&TEXT($V204,"#,##0")&" = $"&TEXT(M204*$V204,"#,##0")&CHAR(10),"")&IF(N204>0,"Pepas Frutos del Bosque: "&N204&" band. x $"&TEXT($V204,"#,##0")&" = $"&TEXT(N204*$V204,"#,##0")&CHAR(10),"")&"................................."&CHAR(10)&"*TOTAL: $"&TEXT(P204,"#,##0")&"*"&CHAR(10)&CHAR(10)&"¡Gracias por tu pedido! 🙏") | T204: =IF(C204="",Config!$B$5,IF(C204>=Config!$B$2,Config!$C$5,Config!$B$5)) | U204: =IF(C204="",Config!$B$8,IF(C204>=Config!$B$2,Config!$C$8,Config!$B$8)) | V204: =IF(C204="",Config!$B$9,IF(C204>=Config!$B$2,Config!$C$9,Config!$B$9))

Sheet Amasijo-Horneado
A1: AMASIJO Y HORNEADO — Producción del día
A2: Se calcula solo según los pedidos de la fecha elegida en la hoja Panel. Solo cantidades físicas — sin precios.
A4: Fecha de entrega a producir: | B4: =Panel!$D$4
A6: RENDIMIENTOS DE REFERENCIA (fijos, confirmados en campo 25/6/2026)
A7: Alfajores por amasijo Masa Maicena/Frutal (1.508 tapas ÷ 2) | F7: 754 | G7: alfajores
A8: Pepas por amasijo Masa Pepas | F8: 1508 | G8: pepas
A9: Tapas malteadas Santafesino por kg (Don Jesús) | F9: 80 | G9: tapas/kg
A10: Tapas por alfajor Santafesino | F10: 3 | G10: tapas
A11: Horneadas por garrafa de 45kg | F11: 45 | G11: horneadas
A12: Horneadas por amasijo | F12: 2 | G12: horneadas
A14: NECESIDAD DE PRODUCCIÓN PARA LA FECHA ELEGIDA
A15: Concepto | B15: Cálculo | C15: Resultado | D15: Unidad
A16: Alfajores masa Maicena/Frutal necesarios | B16: (Maicena x7×7)+(Frutal x7×7)+(Maicena x14×14) | C16: =(Panel!$B$8*7)+(Panel!$B$9*7)+(Panel!$B$11*14) | D16: alfajores
A17: → AMASIJOS Masa Maicena/Frutal a hacer | C17: =ROUNDUP(C16/F7,0) | D17: amasijos
A18: Pepas totales necesarias (todas las variedades) | B18: Suma pedidos Pepas × 18 (unid./bandeja) | C18: =(Panel!$B$12+Panel!$B$13+Panel!$B$14+Panel!$B$15+Panel!$B$16)*18 | D18: pepas
A19: → AMASIJOS Masa Pepas a hacer | C19: =ROUNDUP(C18/F8,0) | D19: amasijos
A20: TOTAL AMASIJOS DEL DÍA (Masa M/F + Masa Pepas) | C20: =C17+C19 | D20: amasijos
A21: =IF(C20>3,"⚠ SUPERA LA JORNADA NORMAL (3 amasijos/día) — evaluar turno extra, adelantar producción a "&(C20-3)&" amasijo(s) del día anterior, o reforzar con más personal.","✓ Dentro de la jornada normal (hasta 3 amasijos).")
A22: Alfajores Santafesino necesarios | C22: =Panel!$B$10*7 | D22: alfajores
A23: Tapas malteadas a comprar a Don Jesús | C23: =C20*F10 | D23: tapas
A24: → KG a pedirle a Don Jesús | C24: =ROUNDUP(C21/F9,1) | D24: kg
A25: Horneadas totales (amasijos M/F + Pepas) × 2 | C25: =(C17+C19)*F12 | D25: horneadas
A26: → GARRAFAS necesarias
A28: INSUMOS DE MASA — necesario vs. stock vs. a comprar
A29: Insumo | B29: Unidad | C29: Cant./amasijo M-F | D29: Cant./amasijo Pepas | E29: Necesario Total | F29: Stock actual | G29: Faltante (comprar) | H29: Fuente/Proveedor
A30: Huevo | B30: u | C30: 40 | D30: 40 | E30: =(C30*$C$17)+(D30*$C$19) | F30: =Stock!$F$5 | G30: =MAX(E30-F30,0) | H30: Huvero
A31: Vainilla | B31: ml | C31: 100 | D31: 0 | E31: =(C31*$C$17)+(D31*$C$19) | F31: =Stock!$F$6 | G31: =MAX(E31-F31,0) | H31: Emeth · Insupar
A32: Colorante amarillo | B32: cm³ | C32: 10 | D32: 0 | E32: =(C32*$C$17)+(D32*$C$19) | F32: =Stock!$F$7 | G32: =MAX(E32-F32,0) | H32: Emeth · Insupar
A33: Miel | B33: cm³ | C33: 50 | D33: 0 | E33: =(C33*$C$17)+(D33*$C$19) | F33: =Stock!$F$8 | G33: =MAX(E33-F33,0) | H33: Apicultor local
A34: Sorbato de potasio | B34: g | C34: 20 | D34: 0 | E34: =(C34*$C$17)+(D34*$C$19) | F34: =Stock!$F$9 | G34: =MAX(E34-F34,0) | H34: CGA · Insupar/ISCO
A35: Propionato de calcio | B35: g | C35: 60 | D35: 0 | E35: =(C35*$C$17)+(D35*$C$19) | F35: =Stock!$F$10 | G35: =MAX(E35-F35,0) | H35: CGA · Insupar/ISCO
A36: Azúcar | B36: kg | C36: 4 | D36: 4 | E36: =(C36*$C$17)+(D36*$C$19) | F36: =Stock!$F$11 | G36: =MAX(E36-F36,0) | H36: GAMA
A37: Margarina | B37: kg | C37: 4 | D37: 4 | E37: =(C37*$C$17)+(D37*$C$19) | F37: =Stock!$F$12 | G37: =MAX(E37-F37,0) | H37: Cordobesa · ISCO Varisco
A38: Maicena (Femag) | B38: kg | C38: 6 | D38: 0 | E38: =(C38*$C$17)+(D38*$C$19) | F38: =Stock!$F$13 | G38: =MAX(E38-F38,0) | H38: Insupar
A39: Harina 000 | B39: kg | C39: 4 | D39: 10 | E39: =(C39*$C$17)+(D39*$C$19) | F39: =Stock!$F$14 | G39: =MAX(E39-F39,0) | H39: Estrella del Paraná · ISCO Varisco
A40: Polvo de hornear | B40: g | C40: 65 | D40: 80 | E40: =(C40*$C$17)+(D40*$C$19) | F40: =Stock!$F$15 | G40: =MAX(E40-F40,0) | H40: Prindal · ISCO Varisco
A41: Bicarbonato de sodio | B41: g | C41: 0 | D41: 5 | E41: =(C41*$C$17)+(D41*$C$19) | F41: =Stock!$F$16 | G41: =MAX(E41-F41,0) | H41: —
A42: Esencia de manteca | B42: ml | C42: 0 | D42: 50 | E42: =(C42*$C$17)+(D42*$C$19) | F42: =Stock!$F$17 | G42: =MAX(E42-F42,0) | H42: —

Sheet Produccion-Real
A1: PRODUCCIÓN REAL — Registro diario (lo que pasó de verdad)
A2: Un renglón por día. Con esto se calcula la merma real y se descuenta el stock. Cargalo al cierre del día.
A4: Fecha | B4: Amasijos M/F hechos | C4: Amasijos Pepas hechos | D4: Tapas M/F producidas (teórico) | E4: Tapas asign. Maicena | F4: Tapas asign. Frutal | G4: Maicena armado real | H4: Frutal armado real | I4: Merma Maicena (u) | J4: Merma Maicena % | K4: Merma Frutal (u) | L4: Merma Frutal % | M4: Tapas Sant. compradas | N4: Santafesino armado real | O4: Merma Santaf. (u) | P4: Merma Santaf. % | Q4: Pepas horneadas (teórico) | R4: Pepas DDL asign. | S4: Pepas DDL armado real | T4: Merma DDL % | U4: Pepas Memb. asign. | V4: Pepas Memb. armado real | W4: Merma Memb. % | X4: Pepas Arán. asign. | Y4: Pepas Arán. armado real | Z4: Merma Arán. % | AA4: Pepas Bat. asign. | AB4: Pepas Bat. armado real | AC4: Merma Bat. % | AD4: Pepas Fr.Bos. asign. | AE4: Pepas Fr.Bos. armado real | AF4: Merma Fr.Bos. % | AG4: [consumo] Huevo | AH4: [consumo] Vainilla | AI4: [consumo] Colorante amarillo | AJ4: [consumo] Miel | AK4: [consumo] Sorbato de potasio | AL4: [consumo] Propionato de calcio | AM4: [consumo] Azúcar | AN4: [consumo] Margarina | AO4: [consumo] Maicena (Femag) | AP4: [consumo] Harina 000 | AQ4: [consumo] Polvo de hornear | AR4: [consumo] Bicarbonato de sodio | AS4: [consumo] Esencia de manteca | AT4: [consumo] Dulce de leche (La Colonias) | AU4: [consumo] Membrillo | AV4: [consumo] Coco rallado | AW4: [consumo] Dulce de batata | AX4: [consumo] Mermelada de arándano | AY4: [consumo] Frutos del bosque | AZ4: [consumo] Azúcar impalpable | BA4: [consumo] Albúmina | BB4: [consumo] Glucosa | BC4: [consumo] Esencia de limón | BD4: [consumo] Ácido acético
D5: =IF(A5="","",B5*1508) | I5: =IF(A5="","",MAX((E5/2)-G5,0)) | J5: =IF(OR(A5="",E5=0),"",I5/(E5/2)) | K5: =IF(A5="","",MAX((F5/2)-H5,0)) | L5: =IF(OR(A5="",F5=0),"",K5/(F5/2)) | O5: =IF(A5="","",MAX((M5/3)-N5,0)) | P5: =IF(OR(A5="",M5=0),"",O5/(M5/3)) | Q5: =IF(A5="","",C5*1508) | T5: =IF(OR(A5="",R5=0),"",MAX(R5-S5,0)/R5) | W5: =IF(OR(A5="",U5=0),"",MAX(U5-V5,0)/U5) | Z5: =IF(OR(A5="",X5=0),"",MAX(X5-Y5,0)/X5) | AC5: =IF(OR(A5="",AA5=0),"",MAX(AA5-AB5,0)/AA5) | AF5: =IF(OR(A5="",AD5=0),"",MAX(AD5-AE5,0)/AD5) | AG5: =IF(A5="",0,(B5*40)+(C5*40)) | AH5: =IF(A5="",0,(B5*100)+(C5*0)) | AI5: =IF(A5="",0,(B5*10)+(C5*0)) | AJ5: =IF(A5="",0,(B5*50)+(C5*0)) | AK5: =IF(A5="",0,(B5*20)+(C5*0)) | AL5: =IF(A5="",0,(B5*60)+(C5*0)) | AM5: =IF(A5="",0,(B5*4)+(C5*4)) | AN5: =IF(A5="",0,(B5*4)+(C5*4)) | AO5: =IF(A5="",0,(B5*6)+(C5*0)) | AP5: =IF(A5="",0,(B5*4)+(C5*10)) | AQ5: =IF(A5="",0,(B5*65)+(C5*80)) | AR5: =IF(A5="",0,(B5*0)+(C5*5)) | AS5: =IF(A5="",0,(B5*0)+(C5*50)) | AT5: =IF(A5="",0,(G5*25.51+N5*30+S5*7.5)/1000) | AU5: =IF(A5="",0,(H5*21.74+V5*7.5)/1000) | AV5: =IF(A5="",0,(G5*0.71)/1000) | AW5: =IF(A5="",0,(AB5*5)/1000) | AX5: =IF(A5="",0,(Y5*7)/1000) | AY5: =IF(A5="",0,(AE5*7)/1000) | AZ5: =IF(A5="",0,ROUNDUP((H5+N5)/115,0)*1.5) | BA5: =IF(A5="",0,ROUNDUP((H5+N5)/115,0)*20) | BB5: =IF(A5="",0,ROUNDUP((H5+N5)/115,0)*80) | BC5: =IF(A5="",0,ROUNDUP((H5+N5)/115,0)*5) | BD5: =IF(A5="",0,ROUNDUP((H5+N5)/115,0)*2.5)
D6: =IF(A6="","",B6*1508) | I6: =IF(A6="","",MAX((E6/2)-G6,0)) | J6: =IF(OR(A6="",E6=0),"",I6/(E6/2)) | K6: =IF(A6="","",MAX((F6/2)-H6,0)) | L6: =IF(OR(A6="",F6=0),"",K6/(F6/2)) | O6: =IF(A6="","",MAX((M6/3)-N6,0)) | P6: =IF(OR(A6="",M6=0),"",O6/(M6/3)) | Q6: =IF(A6="","",C6*1508) | T6: =IF(OR(A6="",R6=0),"",MAX(R6-S6,0)/R6) | W6: =IF(OR(A6="",U6=0),"",MAX(U6-V6,0)/U6) | Z6: =IF(OR(A6="",X6=0),"",MAX(X6-Y6,0)/X6) | AC6: =IF(OR(A6="",AA6=0),"",MAX(AA6-AB6,0)/AA6) | AF6: =IF(OR(A6="",AD6=0),"",MAX(AD6-AE6,0)/AD6) | AG6: =IF(A6="",0,(B6*40)+(C6*40)) | AH6: =IF(A6="",0,(B6*100)+(C6*0)) | AI6: =IF(A6="",0,(B6*10)+(C6*0)) | AJ6: =IF(A6="",0,(B6*50)+(C6*0)) | AK6: =IF(A6="",0,(B6*20)+(C6*0)) | AL6: =IF(A6="",0,(B6*60)+(C6*0)) | AM6: =IF(A6="",0,(B6*4)+(C6*4)) | AN6: =IF(A6="",0,(B6*4)+(C6*4)) | AO6: =IF(A6="",0,(B6*6)+(C6*0)) | AP6: =IF(A6="",0,(B6*4)+(C6*10)) | AQ6: =IF(A6="",0,(B6*65)+(C6*80)) | AR6: =IF(A6="",0,(B6*0)+(C6*5)) | AS6: =IF(A6="",0,(B6*0)+(C6*50)) | AT6: =IF(A6="",0,(G6*25.51+N6*30+S6*7.5)/1000) | AU6: =IF(A6="",0,(H6*21.74+V6*7.5)/1000) | AV6: =IF(A6="",0,(G6*0.71)/1000) | AW6: =IF(A6="",0,(AB6*5)/1000) | AX6: =IF(A6="",0,(Y6*7)/1000) | AY6: =IF(A6="",0,(AE6*7)/1000) | AZ6: =IF(A6="",0,ROUNDUP((H6+N6)/115,0)*1.5) | BA6: =IF(A6="",0,ROUNDUP((H6+N6)/115,0)*20) | BB6: =IF(A6="",0,ROUNDUP((H6+N6)/115,0)*80) | BC6: =IF(A6="",0,ROUNDUP((H6+N6)/115,0)*5) | BD6: =IF(A6="",0,ROUNDUP((H6+N6)/115,0)*2.5)
D7: =IF(A7="","",B7*1508) | I7: =IF(A7="","",MAX((E7/2)-G7,0)) | J7: =IF(OR(A7="",E7=0),"",I7/(E7/2)) | K7: =IF(A7="","",MAX((F7/2)-H7,0)) | L7: =IF(OR(A7="",F7=0),"",K7/(F7/2)) | O7: =IF(A7="","",MAX((M7/3)-N7,0)) | P7: =IF(OR(A7="",M7=0),"",O7/(M7/3)) | Q7: =IF(A7="","",C7*1508) | T7: =IF(OR(A7="",R7=0),"",MAX(R7-S7,0)/R7) | W7: =IF(OR(A7="",U7=0),"",MAX(U7-V7,0)/U7) | Z7: =IF(OR(A7="",X7=0),"",MAX(X7-Y7,0)/X7) | AC7: =IF(OR(A7="",AA7=0),"",MAX(AA7-AB7,0)/AA7) | AF7: =IF(OR(A7="",AD7=0),"",MAX(AD7-AE7,0)/AD7) | AG7: =IF(A7="",0,(B7*40)+(C7*40)) | AH7: =IF(A7="",0,(B7*100)+(C7*0)) | AI7: =IF(A7="",0,(B7*10)+(C7*0)) | AJ7: =IF(A7="",0,(B7*50)+(C7*0)) | AK7: =IF(A7="",0,(B7*20)+(C7*0)) | AL7: =IF(A7="",0,(B7*60)+(C7*0)) | AM7: =IF(A7="",0,(B7*4)+(C7*4)) | AN7: =IF(A7="",0,(B7*4)+(C7*4)) | AO7: =IF(A7="",0,(B7*6)+(C7*0)) | AP7: =IF(A7="",0,(B7*4)+(C7*10)) | AQ7: =IF(A7="",0,(B7*65)+(C7*80)) | AR7: =IF(A7="",0,(B7*0)+(C7*5)) | AS7: =IF(A7="",0,(B7*0)+(C7*50)) | AT7: =IF(A7="",0,(G7*25.51+N7*30+S7*7.5)/1000) | AU7: =IF(A7="",0,(H7*21.74+V7*7.5)/1000) | AV7: =IF(A7="",0,(G7*0.71)/1000) | AW7: =IF(A7="",0,(AB7*5)/1000) | AX7: =IF(A7="",0,(Y7*7)/1000) | AY7: =IF(A7="",0,(AE7*7)/1000) | AZ7: =IF(A7="",0,ROUNDUP((H7+N7)/115,0)*1.5) | BA7: =IF(A7="",0,ROUNDUP((H7+N7)/115,0)*20) | BB7: =IF(A7="",0,ROUNDUP((H7+N7)/115,0)*80) | BC7: =IF(A7="",0,ROUNDUP((H7+N7)/115,0)*5) | BD7: =IF(A7="",0,ROUNDUP((H7+N7)/115,0)*2.5)
D8: =IF(A8="","",B8*1508) | I8: =IF(A8="","",MAX((E8/2)-G8,0)) | J8: =IF(OR(A8="",E8=0),"",I8/(E8/2)) | K8: =IF(A8="","",MAX((F8/2)-H8,0)) | L8: =IF(OR(A8="",F8=0),"",K8/(F8/2)) | O8: =IF(A8="","",MAX((M8/3)-N8,0)) | P8: =IF(OR(A8="",M8=0),"",O8/(M8/3)) | Q8: =IF(A8="","",C8*1508) | T8: =IF(OR(A8="",R8=0),"",MAX(R8-S8,0)/R8) | W8: =IF(OR(A8="",U8=0),"",MAX(U8-V8,0)/U8) | Z8: =IF(OR(A8="",X8=0),"",MAX(X8-Y8,0)/X8) | AC8: =IF(OR(A8="",AA8=0),"",MAX(AA8-AB8,0)/AA8) | AF8: =IF(OR(A8="",AD8=0),"",MAX(AD8-AE8,0)/AD8) | AG8: =IF(A8="",0,(B8*40)+(C8*40)) | AH8: =IF(A8="",0,(B8*100)+(C8*0)) | AI8: =IF(A8="",0,(B8*10)+(C8*0)) | AJ8: =IF(A8="",0,(B8*50)+(C8*0)) | AK8: =IF(A8="",0,(B8*20)+(C8*0)) | AL8: =IF(A8="",0,(B8*60)+(C8*0)) | AM8: =IF(A8="",0,(B8*4)+(C8*4)) | AN8: =IF(A8="",0,(B8*4)+(C8*4)) | AO8: =IF(A8="",0,(B8*6)+(C8*0)) | AP8: =IF(A8="",0,(B8*4)+(C8*10)) | AQ8: =IF(A8="",0,(B8*65)+(C8*80)) | AR8: =IF(A8="",0,(B8*0)+(C8*5)) | AS8: =IF(A8="",0,(B8*0)+(C8*50)) | AT8: =IF(A8="",0,(G8*25.51+N8*30+S8*7.5)/1000) | AU8: =IF(A8="",0,(H8*21.74+V8*7.5)/1000) | AV8: =IF(A8="",0,(G8*0.71)/1000) | AW8: =IF(A8="",0,(AB8*5)/1000) | AX8: =IF(A8="",0,(Y8*7)/1000) | AY8: =IF(A8="",0,(AE8*7)/1000) | AZ8: =IF(A8="",0,ROUNDUP((H8+N8)/115,0)*1.5) | BA8: =IF(A8="",0,ROUNDUP((H8+N8)/115,0)*20) | BB8: =IF(A8="",0,ROUNDUP((H8+N8)/115,0)*80) | BC8: =IF(A8="",0,ROUNDUP((H8+N8)/115,0)*5) | BD8: =IF(A8="",0,ROUNDUP((H8+N8)/115,0)*2.5)
D9: =IF(A9="","",B9*1508) | I9: =IF(A9="","",MAX((E9/2)-G9,0)) | J9: =IF(OR(A9="",E9=0),"",I9/(E9/2)) | K9: =IF(A9="","",MAX((F9/2)-H9,0)) | L9: =IF(OR(A9="",F9=0),"",K9/(F9/2)) | O9: =IF(A9="","",MAX((M9/3)-N9,0)) | P9: =IF(OR(A9="",M9=0),"",O9/(M9/3)) | Q9: =IF(A9="","",C9*1508) | T9: =IF(OR(A9="",R9=0),"",MAX(R9-S9,0)/R9) | W9: =IF(OR(A9="",U9=0),"",MAX(U9-V9,0)/U9) | Z9: =IF(OR(A9="",X9=0),"",MAX(X9-Y9,0)/X9) | AC9: =IF(OR(A9="",AA9=0),"",MAX(AA9-AB9,0)/AA9) | AF9: =IF(OR(A9="",AD9=0),"",MAX(AD9-AE9,0)/AD9) | AG9: =IF(A9="",0,(B9*40)+(C9*40)) | AH9: =IF(A9="",0,(B9*100)+(C9*0)) | AI9: =IF(A9="",0,(B9*10)+(C9*0)) | AJ9: =IF(A9="",0,(B9*50)+(C9*0)) | AK9: =IF(A9="",0,(B9*20)+(C9*0)) | AL9: =IF(A9="",0,(B9*60)+(C9*0)) | AM9: =IF(A9="",0,(B9*4)+(C9*4)) | AN9: =IF(A9="",0,(B9*4)+(C9*4)) | AO9: =IF(A9="",0,(B9*6)+(C9*0)) | AP9: =IF(A9="",0,(B9*4)+(C9*10)) | AQ9: =IF(A9="",0,(B9*65)+(C9*80)) | AR9: =IF(A9="",0,(B9*0)+(C9*5)) | AS9: =IF(A9="",0,(B9*0)+(C9*50)) | AT9: =IF(A9="",0,(G9*25.51+N9*30+S9*7.5)/1000) | AU9: =IF(A9="",0,(H9*21.74+V9*7.5)/1000) | AV9: =IF(A9="",0,(G9*0.71)/1000) | AW9: =IF(A9="",0,(AB9*5)/1000) | AX9: =IF(A9="",0,(Y9*7)/1000) | AY9: =IF(A9="",0,(AE9*7)/1000) | AZ9: =IF(A9="",0,ROUNDUP((H9+N9)/115,0)*1.5) | BA9: =IF(A9="",0,ROUNDUP((H9+N9)/115,0)*20) | BB9: =IF(A9="",0,ROUNDUP((H9+N9)/115,0)*80) | BC9: =IF(A9="",0,ROUNDUP((H9+N9)/115,0)*5) | BD9: =IF(A9="",0,ROUNDUP((H9+N9)/115,0)*2.5)
D10: =IF(A10="","",B10*1508) | I10: =IF(A10="","",MAX((E10/2)-G10,0)) | J10: =IF(OR(A10="",E10=0),"",I10/(E10/2)) | K10: =IF(A10="","",MAX((F10/2)-H10,0)) | L10: =IF(OR(A10="",F10=0),"",K10/(F10/2)) | O10: =IF(A10="","",MAX((M10/3)-N10,0)) | P10: =IF(OR(A10="",M10=0),"",O10/(M10/3)) | Q10: =IF(A10="","",C10*1508) | T10: =IF(OR(A10="",R10=0),"",MAX(R10-S10,0)/R10) | W10: =IF(OR(A10="",U10=0),"",MAX(U10-V10,0)/U10) | Z10: =IF(OR(A10="",X10=0),"",MAX(X10-Y10,0)/X10) | AC10: =IF(OR(A10="",AA10=0),"",MAX(AA10-AB10,0)/AA10) | AF10: =IF(OR(A10="",AD10=0),"",MAX(AD10-AE10,0)/AD10) | AG10: =IF(A10="",0,(B10*40)+(C10*40)) | AH10: =IF(A10="",0,(B10*100)+(C10*0)) | AI10: =IF(A10="",0,(B10*10)+(C10*0)) | AJ10: =IF(A10="",0,(B10*50)+(C10*0)) | AK10: =IF(A10="",0,(B10*20)+(C10*0)) | AL10: =IF(A10="",0,(B10*60)+(C10*0)) | AM10: =IF(A10="",0,(B10*4)+(C10*4)) | AN10: =IF(A10="",0,(B10*4)+(C10*4)) | AO10: =IF(A10="",0,(B10*6)+(C10*0)) | AP10: =IF(A10="",0,(B10*4)+(C10*10)) | AQ10: =IF(A10="",0,(B10*65)+(C10*80)) | AR10: =IF(A10="",0,(B10*0)+(C10*5)) | AS10: =IF(A10="",0,(B10*0)+(C10*50)) | AT10: =IF(A10="",0,(G10*25.51+N10*30+S10*7.5)/1000) | AU10: =IF(A10="",0,(H10*21.74+V10*7.5)/1000) | AV10: =IF(A10="",0,(G10*0.71)/1000) | AW10: =IF(A10="",0,(AB10*5)/1000) | AX10: =IF(A10="",0,(Y10*7)/1000) | AY10: =IF(A10="",0,(AE10*7)/1000) | AZ10: =IF(A10="",0,ROUNDUP((H10+N10)/115,0)*1.5) | BA10: =IF(A10="",0,ROUNDUP((H10+N10)/115,0)*20) | BB10: =IF(A10="",0,ROUNDUP((H10+N10)/115,0)*80) | BC10: =IF(A10="",0,ROUNDUP((H10+N10)/115,0)*5) | BD10: =IF(A10="",0,ROUNDUP((H10+N10)/115,0)*2.5)
D11: =IF(A11="","",B11*1508) | I11: =IF(A11="","",MAX((E11/2)-G11,0)) | J11: =IF(OR(A11="",E11=0),"",I11/(E11/2)) | K11: =IF(A11="","",MAX((F11/2)-H11,0)) | L11: =IF(OR(A11="",F11=0),"",K11/(F11/2)) | O11: =IF(A11="","",MAX((M11/3)-N11,0)) | P11: =IF(OR(A11="",M11=0),"",O11/(M11/3)) | Q11: =IF(A11="","",C11*1508) | T11: =IF(OR(A11="",R11=0),"",MAX(R11-S11,0)/R11) | W11: =IF(OR(A11="",U11=0),"",MAX(U11-V11,0)/U11) | Z11: =IF(OR(A11="",X11=0),"",MAX(X11-Y11,0)/X11) | AC11: =IF(OR(A11="",AA11=0),"",MAX(AA11-AB11,0)/AA11) | AF11: =IF(OR(A11="",AD11=0),"",MAX(AD11-AE11,0)/AD11) | AG11: =IF(A11="",0,(B11*40)+(C11*40)) | AH11: =IF(A11="",0,(B11*100)+(C11*0)) | AI11: =IF(A11="",0,(B11*10)+(C11*0)) | AJ11: =IF(A11="",0,(B11*50)+(C11*0)) | AK11: =IF(A11="",0,(B11*20)+(C11*0)) | AL11: =IF(A11="",0,(B11*60)+(C11*0)) | AM11: =IF(A11="",0,(B11*4)+(C11*4)) | AN11: =IF(A11="",0,(B11*4)+(C11*4)) | AO11: =IF(A11="",0,(B11*6)+(C11*0)) | AP11: =IF(A11="",0,(B11*4)+(C11*10)) | AQ11: =IF(A11="",0,(B11*65)+(C11*80)) | AR11: =IF(A11="",0,(B11*0)+(C11*5)) | AS11: =IF(A11="",0,(B11*0)+(C11*50)) | AT11: =IF(A11="",0,(G11*25.51+N11*30+S11*7.5)/1000) | AU11: =IF(A11="",0,(H11*21.74+V11*7.5)/1000) | AV11: =IF(A11="",0,(G11*0.71)/1000) | AW11: =IF(A11="",0,(AB11*5)/1000) | AX11: =IF(A11="",0,(Y11*7)/1000) | AY11: =IF(A11="",0,(AE11*7)/1000) | AZ11: =IF(A11="",0,ROUNDUP((H11+N11)/115,0)*1.5) | BA11: =IF(A11="",0,ROUNDUP((H11+N11)/115,0)*20) | BB11: =IF(A11="",0,ROUNDUP((H11+N11)/115,0)*80) | BC11: =IF(A11="",0,ROUNDUP((H11+N11)/115,0)*5) | BD11: =IF(A11="",0,ROUNDUP((H11+N11)/115,0)*2.5)
D12: =IF(A12="","",B12*1508) | I12: =IF(A12="","",MAX((E12/2)-G12,0)) | J12: =IF(OR(A12="",E12=0),"",I12/(E12/2)) | K12: =IF(A12="","",MAX((F12/2)-H12,0)) | L12: =IF(OR(A12="",F12=0),"",K12/(F12/2)) | O12: =IF(A12="","",MAX((M12/3)-N12,0)) | P12: =IF(OR(A12="",M12=0),"",O12/(M12/3)) | Q12: =IF(A12="","",C12*1508) | T12: =IF(OR(A12="",R12=0),"",MAX(R12-S12,0)/R12) | W12: =IF(OR(A12="",U12=0),"",MAX(U12-V12,0)/U12) | Z12: =IF(OR(A12="",X12=0),"",MAX(X12-Y12,0)/X12) | AC12: =IF(OR(A12="",AA12=0),"",MAX(AA12-AB12,0)/AA12) | AF12: =IF(OR(A12="",AD12=0),"",MAX(AD12-AE12,0)/AD12) | AG12: =IF(A12="",0,(B12*40)+(C12*40)) | AH12: =IF(A12="",0,(B12*100)+(C12*0)) | AI12: =IF(A12="",0,(B12*10)+(C12*0)) | AJ12: =IF(A12="",0,(B12*50)+(C12*0)) | AK12: =IF(A12="",0,(B12*20)+(C12*0)) | AL12: =IF(A12="",0,(B12*60)+(C12*0)) | AM12: =IF(A12="",0,(B12*4)+(C12*4)) | AN12: =IF(A12="",0,(B12*4)+(C12*4)) | AO12: =IF(A12="",0,(B12*6)+(C12*0)) | AP12: =IF(A12="",0,(B12*4)+(C12*10)) | AQ12: =IF(A12="",0,(B12*65)+(C12*80)) | AR12: =IF(A12="",0,(B12*0)+(C12*5)) | AS12: =IF(A12="",0,(B12*0)+(C12*50)) | AT12: =IF(A12="",0,(G12*25.51+N12*30+S12*7.5)/1000) | AU12: =IF(A12="",0,(H12*21.74+V12*7.5)/1000) | AV12: =IF(A12="",0,(G12*0.71)/1000) | AW12: =IF(A12="",0,(AB12*5)/1000) | AX12: =IF(A12="",0,(Y12*7)/1000) | AY12: =IF(A12="",0,(AE12*7)/1000) | AZ12: =IF(A12="",0,ROUNDUP((H12+N12)/115,0)*1.5) | BA12: =IF(A12="",0,ROUNDUP((H12+N12)/115,0)*20) | BB12: =IF(A12="",0,ROUNDUP((H12+N12)/115,0)*80) | BC12: =IF(A12="",0,ROUNDUP((H12+N12)/115,0)*5) | BD12: =IF(A12="",0,ROUNDUP((H12+N12)/115,0)*2.5)
D13: =IF(A13="","",B13*1508) | I13: =IF(A13="","",MAX((E13/2)-G13,0)) | J13: =IF(OR(A13="",E13=0),"",I13/(E13/2)) | K13: =IF(A13="","",MAX((F13/2)-H13,0)) | L13: =IF(OR(A13="",F13=0),"",K13/(F13/2)) | O13: =IF(A13="","",MAX((M13/3)-N13,0)) | P13: =IF(OR(A13="",M13=0),"",O13/(M13/3)) | Q13: =IF(A13="","",C13*1508) | T13: =IF(OR(A13="",R13=0),"",MAX(R13-S13,0)/R13) | W13: =IF(OR(A13="",U13=0),"",MAX(U13-V13,0)/U13) | Z13: =IF(OR(A13="",X13=0),"",MAX(X13-Y13,0)/X13) | AC13: =IF(OR(A13="",AA13=0),"",MAX(AA13-AB13,0)/AA13) | AF13: =IF(OR(A13="",AD13=0),"",MAX(AD13-AE13,0)/AD13) | AG13: =IF(A13="",0,(B13*40)+(C13*40)) | AH13: =IF(A13="",0,(B13*100)+(C13*0)) | AI13: =IF(A13="",0,(B13*10)+(C13*0)) | AJ13: =IF(A13="",0,(B13*50)+(C13*0)) | AK13: =IF(A13="",0,(B13*20)+(C13*0)) | AL13: =IF(A13="",0,(B13*60)+(C13*0)) | AM13: =IF(A13="",0,(B13*4)+(C13*4)) | AN13: =IF(A13="",0,(B13*4)+(C13*4)) | AO13: =IF(A13="",0,(B13*6)+(C13*0)) | AP13: =IF(A13="",0,(B13*4)+(C13*10)) | AQ13: =IF(A13="",0,(B13*65)+(C13*80)) | AR13: =IF(A13="",0,(B13*0)+(C13*5)) | AS13: =IF(A13="",0,(B13*0)+(C13*50)) | AT13: =IF(A13="",0,(G13*25.51+N13*30+S13*7.5)/1000) | AU13: =IF(A13="",0,(H13*21.74+V13*7.5)/1000) | AV13: =IF(A13="",0,(G13*0.71)/1000) | AW13: =IF(A13="",0,(AB13*5)/1000) | AX13: =IF(A13="",0,(Y13*7)/1000) | AY13: =IF(A13="",0,(AE13*7)/1000) | AZ13: =IF(A13="",0,ROUNDUP((H13+N13)/115,0)*1.5) | BA13: =IF(A13="",0,ROUNDUP((H13+N13)/115,0)*20) | BB13: =IF(A13="",0,ROUNDUP((H13+N13)/115,0)*80) | BC13: =IF(A13="",0,ROUNDUP((H13+N13)/115,0)*5) | BD13: =IF(A13="",0,ROUNDUP((H13+N13)/115,0)*2.5)
D14: =IF(A14="","",B14*1508) | I14: =IF(A14="","",MAX((E14/2)-G14,0)) | J14: =IF(OR(A14="",E14=0),"",I14/(E14/2)) | K14: =IF(A14="","",MAX((F14/2)-H14,0)) | L14: =IF(OR(A14="",F14=0),"",K14/(F14/2)) | O14: =IF(A14="","",MAX((M14/3)-N14,0)) | P14: =IF(OR(A14="",M14=0),"",O14/(M14/3)) | Q14: =IF(A14="","",C14*1508) | T14: =IF(OR(A14="",R14=0),"",MAX(R14-S14,0)/R14) | W14: =IF(OR(A14="",U14=0),"",MAX(U14-V14,0)/U14) | Z14: =IF(OR(A14="",X14=0),"",MAX(X14-Y14,0)/X14) | AC14: =IF(OR(A14="",AA14=0),"",MAX(AA14-AB14,0)/AA14) | AF14: =IF(OR(A14="",AD14=0),"",MAX(AD14-AE14,0)/AD14) | AG14: =IF(A14="",0,(B14*40)+(C14*40)) | AH14: =IF(A14="",0,(B14*100)+(C14*0)) | AI14: =IF(A14="",0,(B14*10)+(C14*0)) | AJ14: =IF(A14="",0,(B14*50)+(C14*0)) | AK14: =IF(A14="",0,(B14*20)+(C14*0)) | AL14: =IF(A14="",0,(B14*60)+(C14*0)) | AM14: =IF(A14="",0,(B14*4)+(C14*4)) | AN14: =IF(A14="",0,(B14*4)+(C14*4)) | AO14: =IF(A14="",0,(B14*6)+(C14*0)) | AP14: =IF(A14="",0,(B14*4)+(C14*10)) | AQ14: =IF(A14="",0,(B14*65)+(C14*80)) | AR14: =IF(A14="",0,(B14*0)+(C14*5)) | AS14: =IF(A14="",0,(B14*0)+(C14*50)) | AT14: =IF(A14="",0,(G14*25.51+N14*30+S14*7.5)/1000) | AU14: =IF(A14="",0,(H14*21.74+V14*7.5)/1000) | AV14: =IF(A14="",0,(G14*0.71)/1000) | AW14: =IF(A14="",0,(AB14*5)/1000) | AX14: =IF(A14="",0,(Y14*7)/1000) | AY14: =IF(A14="",0,(AE14*7)/1000) | AZ14: =IF(A14="",0,ROUNDUP((H14+N14)/115,0)*1.5) | BA14: =IF(A14="",0,ROUNDUP((H14+N14)/115,0)*20) | BB14: =IF(A14="",0,ROUNDUP((H14+N14)/115,0)*80) | BC14: =IF(A14="",0,ROUNDUP((H14+N14)/115,0)*5) | BD14: =IF(A14="",0,ROUNDUP((H14+N14)/115,0)*2.5)
D15: =IF(A15="","",B15*1508) | I15: =IF(A15="","",MAX((E15/2)-G15,0)) | J15: =IF(OR(A15="",E15=0),"",I15/(E15/2)) | K15: =IF(A15="","",MAX((F15/2)-H15,0)) | L15: =IF(OR(A15="",F15=0),"",K15/(F15/2)) | O15: =IF(A15="","",MAX((M15/3)-N15,0)) | P15: =IF(OR(A15="",M15=0),"",O15/(M15/3)) | Q15: =IF(A15="","",C15*1508) | T15: =IF(OR(A15="",R15=0),"",MAX(R15-S15,0)/R15) | W15: =IF(OR(A15="",U15=0),"",MAX(U15-V15,0)/U15) | Z15: =IF(OR(A15="",X15=0),"",MAX(X15-Y15,0)/X15) | AC15: =IF(OR(A15="",AA15=0),"",MAX(AA15-AB15,0)/AA15) | AF15: =IF(OR(A15="",AD15=0),"",MAX(AD15-AE15,0)/AD15) | AG15: =IF(A15="",0,(B15*40)+(C15*40)) | AH15: =IF(A15="",0,(B15*100)+(C15*0)) | AI15: =IF(A15="",0,(B15*10)+(C15*0)) | AJ15: =IF(A15="",0,(B15*50)+(C15*0)) | AK15: =IF(A15="",0,(B15*20)+(C15*0)) | AL15: =IF(A15="",0,(B15*60)+(C15*0)) | AM15: =IF(A15="",0,(B15*4)+(C15*4)) | AN15: =IF(A15="",0,(B15*4)+(C15*4)) | AO15: =IF(A15="",0,(B15*6)+(C15*0)) | AP15: =IF(A15="",0,(B15*4)+(C15*10)) | AQ15: =IF(A15="",0,(B15*65)+(C15*80)) | AR15: =IF(A15="",0,(B15*0)+(C15*5)) | AS15: =IF(A15="",0,(B15*0)+(C15*50)) | AT15: =IF(A15="",0,(G15*25.51+N15*30+S15*7.5)/1000) | AU15: =IF(A15="",0,(H15*21.74+V15*7.5)/1000) | AV15: =IF(A15="",0,(G15*0.71)/1000) | AW15: =IF(A15="",0,(AB15*5)/1000) | AX15: =IF(A15="",0,(Y15*7)/1000) | AY15: =IF(A15="",0,(AE15*7)/1000) | AZ15: =IF(A15="",0,ROUNDUP((H15+N15)/115,0)*1.5) | BA15: =IF(A15="",0,ROUNDUP((H15+N15)/115,0)*20) | BB15: =IF(A15="",0,ROUNDUP((H15+N15)/115,0)*80) | BC15: =IF(A15="",0,ROUNDUP((H15+N15)/115,0)*5) | BD15: =IF(A15="",0,ROUNDUP((H15+N15)/115,0)*2.5)
D16: =IF(A16="","",B16*1508) | I16: =IF(A16="","",MAX((E16/2)-G16,0)) | J16: =IF(OR(A16="",E16=0),"",I16/(E16/2)) | K16: =IF(A16="","",MAX((F16/2)-H16,0)) | L16: =IF(OR(A16="",F16=0),"",K16/(F16/2)) | O16: =IF(A16="","",MAX((M16/3)-N16,0)) | P16: =IF(OR(A16="",M16=0),"",O16/(M16/3)) | Q16: =IF(A16="","",C16*1508) | T16: =IF(OR(A16="",R16=0),"",MAX(R16-S16,0)/R16) | W16: =IF(OR(A16="",U16=0),"",MAX(U16-V16,0)/U16) | Z16: =IF(OR(A16="",X16=0),"",MAX(X16-Y16,0)/X16) | AC16: =IF(OR(A16="",AA16=0),"",MAX(AA16-AB16,0)/AA16) | AF16: =IF(OR(A16="",AD16=0),"",MAX(AD16-AE16,0)/AD16) | AG16: =IF(A16="",0,(B16*40)+(C16*40)) | AH16: =IF(A16="",0,(B16*100)+(C16*0)) | AI16: =IF(A16="",0,(B16*10)+(C16*0)) | AJ16: =IF(A16="",0,(B16*50)+(C16*0)) | AK16: =IF(A16="",0,(B16*20)+(C16*0)) | AL16: =IF(A16="",0,(B16*60)+(C16*0)) | AM16: =IF(A16="",0,(B16*4)+(C16*4)) | AN16: =IF(A16="",0,(B16*4)+(C16*4)) | AO16: =IF(A16="",0,(B16*6)+(C16*0)) | AP16: =IF(A16="",0,(B16*4)+(C16*10)) | AQ16: =IF(A16="",0,(B16*65)+(C16*80)) | AR16: =IF(A16="",0,(B16*0)+(C16*5)) | AS16: =IF(A16="",0,(B16*0)+(C16*50)) | AT16: =IF(A16="",0,(G16*25.51+N16*30+S16*7.5)/1000) | AU16: =IF(A16="",0,(H16*21.74+V16*7.5)/1000) | AV16: =IF(A16="",0,(G16*0.71)/1000) | AW16: =IF(A16="",0,(AB16*5)/1000) | AX16: =IF(A16="",0,(Y16*7)/1000) | AY16: =IF(A16="",0,(AE16*7)/1000) | AZ16: =IF(A16="",0,ROUNDUP((H16+N16)/115,0)*1.5) | BA16: =IF(A16="",0,ROUNDUP((H16+N16)/115,0)*20) | BB16: =IF(A16="",0,ROUNDUP((H16+N16)/115,0)*80) | BC16: =IF(A16="",0,ROUNDUP((H16+N16)/115,0)*5) | BD16: =IF(A16="",0,ROUNDUP((H16+N16)/115,0)*2.5)
... D154: =IF(A154="","",B154*1508) | I154: =IF(A154="","",MAX((E154/2)-G154,0)) | J154: =IF(OR(A154="",E154=0),"",I154/(E154/2)) | K154: =IF(A154="","",MAX((F154/2)-H154,0)) | L154: =IF(OR(A154="",F154=0),"",K154/(F154/2)) | O154: =IF(A154="","",MAX((M154/3)-N154,0)) | P154: =IF(OR(A154="",M154=0),"",O154/(M154/3)) | Q154: =IF(A154="","",C154*1508) | T154: =IF(OR(A154="",R154=0),"",MAX(R154-S154,0)/R154) | W154: =IF(OR(A154="",U154=0),"",MAX(U154-V154,0)/U154) | Z154: =IF(OR(A154="",X154=0),"",MAX(X154-Y154,0)/X154) | AC154: =IF(OR(A154="",AA154=0),"",MAX(AA154-AB154,0)/AA154) | AF154: =IF(OR(A154="",AD154=0),"",MAX(AD154-AE154,0)/AD154) | AG154: =IF(A154="",0,(B154*40)+(C154*40)) | AH154: =IF(A154="",0,(B154*100)+(C154*0)) | AI154: =IF(A154="",0,(B154*10)+(C154*0)) | AJ154: =IF(A154="",0,(B154*50)+(C154*0)) | AK154: =IF(A154="",0,(B154*20)+(C154*0)) | AL154: =IF(A154="",0,(B154*60)+(C154*0)) | AM154: =IF(A154="",0,(B154*4)+(C154*4)) | AN154: =IF(A154="",0,(B154*4)+(C154*4)) | AO154: =IF(A154="",0,(B154*6)+(C154*0)) | AP154: =IF(A154="",0,(B154*4)+(C154*10)) | AQ154: =IF(A154="",0,(B154*65)+(C154*80)) | AR154: =IF(A154="",0,(B154*0)+(C154*5)) | AS154: =IF(A154="",0,(B154*0)+(C154*50)) | AT154: =IF(A154="",0,(G154*25.51+N154*30+S154*7.5)/1000) | AU154: =IF(A154="",0,(H154*21.74+V154*7.5)/1000) | AV154: =IF(A154="",0,(G154*0.71)/1000) | AW154: =IF(A154="",0,(AB154*5)/1000) | AX154: =IF(A154="",0,(Y154*7)/1000) | AY154: =IF(A154="",0,(AE154*7)/1000) | AZ154: =IF(A154="",0,ROUNDUP((H154+N154)/115,0)*1.5) | BA154: =IF(A154="",0,ROUNDUP((H154+N154)/115,0)*20) | BB154: =IF(A154="",0,ROUNDUP((H154+N154)/115,0)*80) | BC154: =IF(A154="",0,ROUNDUP((H154+N154)/115,0)*5) | BD154: =IF(A154="",0,ROUNDUP((H154+N154)/115,0)*2.5)

Sheet Stock
A1: STOCK — Inventario real de insumos
A2: Stock inicial (lo cargás una vez) + Recepciones de Compra − Consumo real de Producción Real = Stock actual.
A4: Insumo | B4: Unidad | C4: Stock inicial | D4: Recibido (acum.) | E4: Consumido (acum.) | F4: STOCK ACTUAL | G4: Última actualización
A5: Huevo | B5: u | C5: 0 | D5: =SUMIF('Orden de Compra'!$B$43:$B$242,A5,'Orden de Compra'!$C$43:$C$242) | E5: =SUM('Produccion-Real'!$AG$5:$AG$154) | F5: =C5+D5-E5 | G5: =TODAY()
A6: Vainilla | B6: ml | C6: 0 | D6: =SUMIF('Orden de Compra'!$B$43:$B$242,A6,'Orden de Compra'!$C$43:$C$242) | E6: =SUM('Produccion-Real'!$AH$5:$AH$154) | F6: =C6+D6-E6 | G6: =TODAY()
A7: Colorante amarillo | B7: cm³ | C7: 0 | D7: =SUMIF('Orden de Compra'!$B$43:$B$242,A7,'Orden de Compra'!$C$43:$C$242) | E7: =SUM('Produccion-Real'!$AI$5:$AI$154) | F7: =C7+D7-E7 | G7: =TODAY()
A8: Miel | B8: cm³ | C8: 0 | D8: =SUMIF('Orden de Compra'!$B$43:$B$242,A8,'Orden de Compra'!$C$43:$C$242) | E8: =SUM('Produccion-Real'!$AJ$5:$AJ$154) | F8: =C8+D8-E8 | G8: =TODAY()
A9: Sorbato de potasio | B9: g | C9: 0 | D9: =SUMIF('Orden de Compra'!$B$43:$B$242,A9,'Orden de Compra'!$C$43:$C$242) | E9: =SUM('Produccion-Real'!$AK$5:$AK$154) | F9: =C9+D9-E9 | G9: =TODAY()
A10: Propionato de calcio | B10: g | C10: 0 | D10: =SUMIF('Orden de Compra'!$B$43:$B$242,A10,'Orden de Compra'!$C$43:$C$242) | E10: =SUM('Produccion-Real'!$AL$5:$AL$154) | F10: =C10+D10-E10 | G10: =TODAY()
A11: Azúcar | B11: kg | C11: 0 | D11: =SUMIF('Orden de Compra'!$B$43:$B$242,A11,'Orden de Compra'!$C$43:$C$242) | E11: =SUM('Produccion-Real'!$AM$5:$AM$154) | F11: =C11+D11-E11 | G11: =TODAY()
A12: Margarina | B12: kg | C12: 0 | D12: =SUMIF('Orden de Compra'!$B$43:$B$242,A12,'Orden de Compra'!$C$43:$C$242) | E12: =SUM('Produccion-Real'!$AN$5:$AN$154) | F12: =C12+D12-E12 | G12: =TODAY()
A13: Maicena (Femag) | B13: kg | C13: 0 | D13: =SUMIF('Orden de Compra'!$B$43:$B$242,A13,'Orden de Compra'!$C$43:$C$242) | E13: =SUM('Produccion-Real'!$AO$5:$AO$154) | F13: =C13+D13-E13 | G13: =TODAY()
A14: Harina 000 | B14: kg | C14: 0 | D14: =SUMIF('Orden de Compra'!$B$43:$B$242,A14,'Orden de Compra'!$C$43:$C$242) | E14: =SUM('Produccion-Real'!$AP$5:$AP$154) | F14: =C14+D14-E14 | G14: =TODAY()
A15: Polvo de hornear | B15: g | C15: 0 | D15: =SUMIF('Orden de Compra'!$B$43:$B$242,A15,'Orden de Compra'!$C$43:$C$242) | E15: =SUM('Produccion-Real'!$AQ$5:$AQ$154) | F15: =C15+D15-E15 | G15: =TODAY()
A16: Bicarbonato de sodio | B16: g | C16: 0 | D16: =SUMIF('Orden de Compra'!$B$43:$B$242,A16,'Orden de Compra'!$C$43:$C$242) | E16: =SUM('Produccion-Real'!$AR$5:$AR$154) | F16: =C16+D16-E16 | G16: =TODAY()
A17: Esencia de manteca | B17: ml | C17: 0 | D17: =SUMIF('Orden de Compra'!$B$43:$B$242,A17,'Orden de Compra'!$C$43:$C$242) | E17: =SUM('Produccion-Real'!$AS$5:$AS$154) | F17: =C17+D17-E17 | G17: =TODAY()
A18: Dulce de leche (La Colonias) | B18: kg | C18: 0 | D18: =SUMIF('Orden de Compra'!$B$43:$B$242,A18,'Orden de Compra'!$C$43:$C$242) | E18: =SUM('Produccion-Real'!$AT$5:$AT$154) | F18: =C18+D18-E18 | G18: =TODAY()
A19: Membrillo | B19: kg | C19: 0 | D19: =SUMIF('Orden de Compra'!$B$43:$B$242,A19,'Orden de Compra'!$C$43:$C$242) | E19: =SUM('Produccion-Real'!$AU$5:$AU$154) | F19: =C19+D19-E19 | G19: =TODAY()
A20: Coco rallado | B20: kg | C20: 0 | D20: =SUMIF('Orden de Compra'!$B$43:$B$242,A20,'Orden de Compra'!$C$43:$C$242) | E20: =SUM('Produccion-Real'!$AV$5:$AV$154) | F20: =C20+D20-E20 | G20: =TODAY()
A21: Dulce de batata | B21: kg | C21: 0 | D21: =SUMIF('Orden de Compra'!$B$43:$B$242,A21,'Orden de Compra'!$C$43:$C$242) | E21: =SUM('Produccion-Real'!$AW$5:$AW$154) | F21: =C21+D21-E21 | G21: =TODAY()
A22: Mermelada de arándano | B22: kg | C22: 0 | D22: =SUMIF('Orden de Compra'!$B$43:$B$242,A22,'Orden de Compra'!$C$43:$C$242) | E22: =SUM('Produccion-Real'!$AX$5:$AX$154) | F22: =C22+D22-E22 | G22: =TODAY()
A23: Frutos del bosque | B23: kg | C23: 0 | D23: =SUMIF('Orden de Compra'!$B$43:$B$242,A23,'Orden de Compra'!$C$43:$C$242) | E23: =SUM('Produccion-Real'!$AY$5:$AY$154) | F23: =C23+D23-E23 | G23: =TODAY()
A24: Azúcar impalpable | B24: kg | C24: 0 | D24: =SUMIF('Orden de Compra'!$B$43:$B$242,A24,'Orden de Compra'!$C$43:$C$242) | E24: =SUM('Produccion-Real'!$AZ$5:$AZ$154) | F24: =C24+D24-E24 | G24: =TODAY()
A25: Albúmina | B25: g | C25: 0 | D25: =SUMIF('Orden de Compra'!$B$43:$B$242,A25,'Orden de Compra'!$C$43:$C$242) | E25: =SUM('Produccion-Real'!$BA$5:$BA$154) | F25: =C25+D25-E25 | G25: =TODAY()
A26: Glucosa | B26: g | C26: 0 | D26: =SUMIF('Orden de Compra'!$B$43:$B$242,A26,'Orden de Compra'!$C$43:$C$242) | E26: =SUM('Produccion-Real'!$BB$5:$BB$154) | F26: =C26+D26-E26 | G26: =TODAY()
A27: Esencia de limón | B27: ml | C27: 0 | D27: =SUMIF('Orden de Compra'!$B$43:$B$242,A27,'Orden de Compra'!$C$43:$C$242) | E27: =SUM('Produccion-Real'!$BC$5:$BC$154) | F27: =C27+D27-E27 | G27: =TODAY()
A28: Ácido acético | B28: ml | C28: 0 | D28: =SUMIF('Orden de Compra'!$B$43:$B$242,A28,'Orden de Compra'!$C$43:$C$242) | E28: =SUM('Produccion-Real'!$BD$5:$BD$154) | F28: =C28+D28-E28 | G28: =TODAY()
A29: PACKAGING Y TAPAS SANTAFESINO — consumo según pedidos marcados 'Entregado' en Pedidos
A30: Tapas malteadas (Don Jesús) | B30: u | C30: 0 | D30: =SUMIF('Orden de Compra'!$B$43:$B$242,A30,'Orden de Compra'!$C$43:$C$242) | E30: =SUMIFS(Pedidos!$H$5:$H$204,Pedidos!$Q$5:$Q$204,"Entregado")*7*3 | F30: =C30+D30-E30 | G30: =TODAY()
A31: Bandeja plástica x7 | B31: u | C31: 0 | D31: =SUMIF('Orden de Compra'!$B$43:$B$242,A31,'Orden de Compra'!$C$43:$C$242) | E31: =SUMIFS(Pedidos!$F$5:$F$204,Pedidos!$Q$5:$Q$204,"Entregado")+SUMIFS(Pedidos!$G$5:$G$204,Pedidos!$Q$5:$Q$204,"Entregado")+SUMIFS(Pedidos!$H$5:$H$204,Pedidos!$Q$5:$Q$204,"Entregado") | F31: =C31+D31-E31 | G31: =TODAY()
A32: Bolsa impresa x7 (RNPA) | B32: u | C32: 0 | D32: =SUMIF('Orden de Compra'!$B$43:$B$242,A32,'Orden de Compra'!$C$43:$C$242) | E32: =SUMIFS(Pedidos!$F$5:$F$204,Pedidos!$Q$5:$Q$204,"Entregado")+SUMIFS(Pedidos!$G$5:$G$204,Pedidos!$Q$5:$Q$204,"Entregado")+SUMIFS(Pedidos!$H$5:$H$204,Pedidos!$Q$5:$Q$204,"Entregado") | F32: =C32+D32-E32 | G32: =TODAY()
A33: Caja x7 | B33: u | C33: 0 | D33: =SUMIF('Orden de Compra'!$B$43:$B$242,A33,'Orden de Compra'!$C$43:$C$242) | E33: =ROUNDUP((SUMIFS(Pedidos!$F$5:$F$204,Pedidos!$Q$5:$Q$204,"Entregado")+SUMIFS(Pedidos!$G$5:$G$204,Pedidos!$Q$5:$Q$204,"Entregado")+SUMIFS(Pedidos!$H$5:$H$204,Pedidos!$Q$5:$Q$204,"Entregado"))/15,0) | F33: =C33+D33-E33 | G33: =TODAY()
A34: Bandeja con tapa x14 | B34: u | C34: 0 | D34: =SUMIF('Orden de Compra'!$B$43:$B$242,A34,'Orden de Compra'!$C$43:$C$242) | E34: =SUMIFS(Pedidos!$I$5:$I$204,Pedidos!$Q$5:$Q$204,"Entregado") | F34: =C34+D34-E34 | G34: =TODAY()
A35: Etiqueta cierre x14 | B35: u | C35: 0 | D35: =SUMIF('Orden de Compra'!$B$43:$B$242,A35,'Orden de Compra'!$C$43:$C$242) | E35: =SUMIFS(Pedidos!$I$5:$I$204,Pedidos!$Q$5:$Q$204,"Entregado") | F35: =C35+D35-E35 | G35: =TODAY()
A36: Bandeja abierta 320g Pepas | B36: u | C36: 0 | D36: =SUMIF('Orden de Compra'!$B$43:$B$242,A36,'Orden de Compra'!$C$43:$C$242) | E36: =SUMIFS(Pedidos!$J$5:$J$204,Pedidos!$Q$5:$Q$204,"Entregado")+SUMIFS(Pedidos!$K$5:$K$204,Pedidos!$Q$5:$Q$204,"Entregado")+SUMIFS(Pedidos!$L$5:$L$204,Pedidos!$Q$5:$Q$204,"Entregado")+SUMIFS(Pedidos!$M$5:$M$204,Pedidos!$Q$5:$Q$204,"Entregado")+SUMIFS(Pedidos!$N$5:$N$204,Pedidos!$Q$5:$Q$204,"Entregado") | F36: =C36+D36-E36 | G36: =TODAY()
A37: Etiqueta Pepas | B37: u | C37: 0 | D37: =SUMIF('Orden de Compra'!$B$43:$B$242,A37,'Orden de Compra'!$C$43:$C$242) | E37: =SUMIFS(Pedidos!$J$5:$J$204,Pedidos!$Q$5:$Q$204,"Entregado")+SUMIFS(Pedidos!$K$5:$K$204,Pedidos!$Q$5:$Q$204,"Entregado")+SUMIFS(Pedidos!$L$5:$L$204,Pedidos!$Q$5:$Q$204,"Entregado")+SUMIFS(Pedidos!$M$5:$M$204,Pedidos!$Q$5:$Q$204,"Entregado")+SUMIFS(Pedidos!$N$5:$N$204,Pedidos!$Q$5:$Q$204,"Entregado") | F37: =C37+D37-E37 | G37: =TODAY()

Sheet Relleno-Glase
A1: RELLENO Y GLASÉ — Producción del día
A2: Se calcula solo según los pedidos de la fecha elegida en Panel.
A4: Fecha de entrega a producir: | B4: =Panel!$D$4
A6: ALFAJORES/PEPAS POR LÍNEA (fecha elegida)
A7: Maicena (alfajores, x7+x14) | B7: =(Panel!$B$8*7)+(Panel!$B$11*14)
A8: Frutal (alfajores) | B8: =Panel!$B$9*7
A9: Santafesino (alfajores) | B9: =Panel!$B$10*7
A10: Pepas DDL (unidades) | B10: =Panel!$B$12*18
A11: Pepas Membrillo (unidades) | B11: =Panel!$B$13*18
A12: Pepas Arándano (unidades) | B12: =Panel!$B$14*18
A13: Pepas Batata (unidades) | B13: =Panel!$B$15*18
A14: Pepas Frutos del Bosque (unidades) | B14: =Panel!$B$16*18
A16: RELLENOS Y GLASÉ — necesario vs. stock vs. a comprar
A17: Insumo | B17: Unidad | C17: Cálculo | D17: Necesario Total | E17: Stock actual | F17: Faltante (comprar) | G17: Nota
